<mujoco model="leap_right">
  <compiler angle="radian" meshdir="./" autolimits="true"/>

  <option gravity="0 0 0"/>

  <default>
    <default class="leap_hand">
      <joint damping="0.05"/>
      <position kp="3" dampratio="1"/>
      <geom density="800"/>

      <default class="visual">
        <geom type="mesh" contype="0" conaffinity="0" group="2" rgba="0.7 0.7 0.7 1"/>
      </default>
      <default class="collision">
        <geom group="3" mass="0" contype="0" conaffinity="0" rgba="0 0 0 0"/>
      </default>
    </default>
  </default>

  <visual>
    <global offwidth="1280" offheight="1280"/>
    <quality shadowsize="4096"/>
  </visual>

  <asset>
    <texture type="skybox" builtin="gradient" rgb1="0.3 0.5 0.7" rgb2="0 0 0" width="512" height="3072"/>
    <texture type="2d" name="groundplane" builtin="checker" mark="edge" rgb1="0.2 0.3 0.4" rgb2="0.1 0.2 0.3" markrgb="0.8 0.8 0.8" width="300" height="300"/>
    <material name="groundplane" texture="groundplane" texrepeat="5 5" reflectance="0.2"/>
    <material name="hand_gray" rgba="0.65 0.65 0.65 1"/>
    <material name="hand_dark" rgba="0.3 0.3 0.3 1"/>

    <mesh name="palm_lower" file="meshes/visual/palm_lower.obj"/>
    <mesh name="mcp_joint" file="meshes/visual/mcp_joint.obj"/>
    <mesh name="pip" file="meshes/visual/pip.obj"/>
    <mesh name="dip" file="meshes/visual/dip.obj"/>
    <mesh name="fingertip" file="meshes/visual/fingertip.obj"/>
    <mesh name="white_tip" file="meshes/collision/white_tip.obj"/>
    <mesh name="thumb_pip" file="meshes/visual/thumb_pip.obj"/>
    <mesh name="thumb_dip" file="meshes/visual/thumb_dip.obj"/>
    <mesh name="thumb_fingertip" file="meshes/visual/thumb_fingertip.obj"/>
    <mesh name="white_tip_thumb" file="meshes/collision/white_tip_thumb.obj"/>
  </asset>

  <worldbody>
    <light pos="0 0 1.5" dir="0 0 -1" directional="true"/>
    <light pos="0.5 0.5 1" dir="-0.5 -0.5 -1"/>
    <geom name="floor" size="0 0 0.05" type="plane" material="groundplane"/>

    <!-- Palm body -->
    <body name="palm" childclass="leap_hand">
      <geom pos="0.0346999 0.06375 0.0779998" quat="0.707109 0 -0.707105 0" type="mesh" mesh="palm_lower" class="visual" material="hand_gray"/>

      <!-- Index finger (joints: 1, 0, 2, 3) -->
      <body name="mcp_joint" pos="0.0187 0.061 0.0909999" quat="0.707109 0.707105 0 0">
        <inertial pos="0 0 0" quat="0.388585 0.626468 -0.324549 0.592628" mass="0.044" diaginertia="1.47756e-05 1.31982e-05 6.0802e-06"/>
        <joint name="1" axis="0 0 -1" range="-0.314 2.23"/>
        <geom pos="0.0084 0.0077 0.01465" type="mesh" mesh="mcp_joint" class="visual" material="hand_dark"/>
        <body name="pip" pos="-0.0122 0.0381 0.0145" quat="0.500003 -0.5 -0.499997 0.5">
          <inertial pos="0 0 0" quat="0.709913 0.704273 -0.000363156 0.00475427" mass="0.032" diaginertia="4.7981e-06 4.23406e-06 2.86184e-06"/>
          <joint name="0" axis="0 0 -1" range="-1.047 1.047"/>
          <geom pos="0.0096 0.0002 0.0007" quat="0.500003 -0.5 -0.5 -0.499997" type="mesh" mesh="pip" class="visual" material="hand_gray"/>
          <body name="dip" pos="0.015 0.0143 -0.013" quat="0.500003 0.5 -0.5 0.499997">
            <inertial pos="0 0 0" quat="-0.252689 0.659216 0.238844 0.666735" mass="0.037" diaginertia="6.68256e-06 6.24841e-06 5.02002e-06"/>
            <joint name="2" axis="0 0 -1" range="-0.506 1.885"/>
            <geom pos="0.0211 -0.0084 0.0097" quat="2.67949e-08 -1 0 0" type="mesh" mesh="dip" class="visual" material="hand_gray"/>
            <body name="fingertip" pos="0 -0.0361 0.0002">
              <inertial pos="0 0 0" quat="0.706755 0.706755 0.0223155 0.0223155" mass="0.016" diaginertia="3.37527e-06 2.863e-06 1.54873e-06"/>
              <joint name="3" axis="0 0 -1" range="-0.366 2.042"/>
              <geom pos="0.0132 -0.0061 0.0144" quat="2.67949e-08 1 0 0" type="mesh" mesh="fingertip" class="visual" material="hand_gray"/>
              <geom type="mesh" mesh="white_tip" class="visual" material="hand_dark"/>
            </body>
          </body>
        </body>
      </body>

      <!-- Middle finger (joints: 5, 4, 6, 7) -->
      <body name="mcp_joint_2" pos="0.0187 0.0156 0.0908999" quat="0.707109 0.707105 0 0">
        <inertial pos="0 0 0" quat="0.388585 0.626468 -0.324549 0.592628" mass="0.044" diaginertia="1.47756e-05 1.31982e-05 6.0802e-06"/>
        <joint name="5" axis="0 0 -1" range="-0.314 2.23"/>
        <geom pos="0.0084 0.0077 0.01465" type="mesh" mesh="mcp_joint" class="visual" material="hand_dark"/>
        <body name="pip_2" pos="-0.0122 0.0381 0.0145" quat="0.500003 -0.5 -0.499997 0.5">
          <inertial pos="0 0 0" quat="0.709913 0.704273 -0.000363156 0.00475427" mass="0.032" diaginertia="4.7981e-06 4.23406e-06 2.86184e-06"/>
          <joint name="4" axis="0 0 -1" range="-1.047 1.047"/>
          <geom pos="0.0096 0.0003 0.0007" quat="0.500003 -0.5 -0.5 -0.499997" type="mesh" mesh="pip" class="visual" material="hand_gray"/>
          <body name="dip_2" pos="0.015 0.0143 -0.013" quat="0.500003 0.5 -0.5 0.499997">
            <inertial pos="0 0 0" quat="-0.252689 0.659216 0.238844 0.666735" mass="0.037" diaginertia="6.68256e-06 6.24841e-06 5.02002e-06"/>
            <joint name="6" axis="0 0 -1" range="-0.506 1.885"/>
            <geom pos="0.0211 -0.0084 0.0097" quat="1.32679e-06 -1 0 0" type="mesh" mesh="dip" class="visual" material="hand_gray"/>
            <body name="fingertip_2" pos="0 -0.0361 0.0002">
              <inertial pos="0 0 0" quat="0.706755 0.706755 0.0223155 0.0223155" mass="0.016" diaginertia="3.37527e-06 2.863e-06 1.54873e-06"/>
              <joint name="7" axis="0 0 -1" range="-0.366 2.042"/>
              <geom pos="0.0132 -0.0061 0.0145" quat="1.32679e-06 1 0 0" type="mesh" mesh="fingertip" class="visual" material="hand_gray"/>
              <geom type="mesh" mesh="white_tip" class="visual" material="hand_dark"/>
            </body>
          </body>
        </body>
      </body>

      <!-- Ring finger (joints: 9, 8, 10, 11) -->
      <body name="mcp_joint_3" pos="0.0187 -0.0298 0.0909099" quat="0.707109 0.707105 0 0">
        <inertial pos="0 0 0" quat="0.388585 0.626468 -0.324549 0.592628" mass="0.044" diaginertia="1.47756e-05 1.31982e-05 6.0802e-06"/>
        <joint name="9" axis="0 0 -1" range="-0.314 2.23"/>
        <geom pos="0.0084 0.0077 0.01465" type="mesh" mesh="mcp_joint" class="visual" material="hand_dark"/>
        <body name="pip_3" pos="-0.0122 0.0381 0.0145" quat="0.500003 -0.5 -0.499997 0.5">
          <inertial pos="0 0 0" quat="0.709913 0.704273 -0.000363156 0.00475427" mass="0.032" diaginertia="4.7981e-06 4.23406e-06 2.86184e-06"/>
          <joint name="8" axis="0 0 -1" range="-1.047 1.047"/>
          <geom pos="0.0096 0.0003 0.0007" quat="0.500003 -0.5 -0.5 -0.499997" type="mesh" mesh="pip" class="visual" material="hand_gray"/>
          <body name="dip_3" pos="0.015 0.0143 -0.013" quat="0.500003 0.5 -0.5 0.499997">
            <inertial pos="0 0 0" quat="-0.252689 0.659216 0.238844 0.666735" mass="0.037" diaginertia="6.68256e-06 6.24841e-06 5.02002e-06"/>
            <joint name="10" axis="0 0 -1" range="-0.506 1.885"/>
            <geom pos="0.0211 -0.0084 0.0097" quat="1.32679e-06 -1 0 0" type="mesh" mesh="dip" class="visual" material="hand_gray"/>
            <body name="fingertip_3" pos="0 -0.03609 0.0002">
              <inertial pos="0 0 0" quat="0.706755 0.706755 0.0223155 0.0223155" mass="0.016" diaginertia="3.37527e-06 2.863e-06 1.54873e-06"/>
              <joint name="11" axis="0 0 -1" range="-0.366 2.042"/>
              <geom pos="0.0132 -0.0061 0.0145" quat="1.32679e-06 1 0 0" type="mesh" mesh="fingertip" class="visual" material="hand_gray"/>
              <geom type="mesh" mesh="white_tip" class="visual" material="hand_dark"/>
            </body>
          </body>
        </body>
      </body>

      <!-- Thumb (joints: 12, 13, 14, 15) -->
      <body name="thumb_temp_base" pos="0.0215996 0.0368 0.0286999">
        <inertial pos="0 0 0" quat="0.709913 0.704273 -0.000363156 0.00475427" mass="0.032" diaginertia="4.7981e-06 4.23406e-06 2.86184e-06"/>
        <joint name="12" axis="0 0 -1" range="-0.349 2.094"/>
        <geom pos="-0.0053 0.0003 0.00078" quat="0.500003 -0.5 -0.5 -0.499997" type="mesh" mesh="pip" class="visual" material="hand_gray"/>
        <body name="thumb_pip" pos="0 0.0143 -0.013" quat="0.500003 0.5 -0.5 0.499997">
          <inertial pos="0 0 0" mass="0.003" diaginertia="5.93e-07 5.49e-07 2.24e-07"/>
          <joint name="13" axis="0 0 -1" range="-0.47 2.443"/>
          <geom pos="0.01196 0 -0.0158" quat="0.707109 0.707105 0 0" type="mesh" mesh="thumb_pip" class="visual" material="hand_gray"/>
          <body name="thumb_dip" pos="0 0.0145 -0.017" quat="0.707109 -0.707105 0 0">
            <inertial pos="0 0 0" quat="0.708624 0.704906 0.00637342 0.0303153" mass="0.038" diaginertia="8.48742e-06 7.67823e-06 3.82835e-06"/>
            <joint name="14" axis="0 0 -1" range="-1.2 1.9"/>
            <geom pos="0.0439 0.0579 -0.0086" type="mesh" mesh="thumb_dip" class="visual" material="hand_gray"/>
            <body name="thumb_fingertip" pos="0 0.0466 0.0002" quat="1.32679e-06 0 0 1">
              <inertial pos="0 0 0" quat="0.704307 0.709299 0.006848 -0.0282727" mass="0.049" diaginertia="2.03882e-05 1.98443e-05 4.32049e-06"/>
              <joint name="15" axis="0 0 -1" range="-1.34 1.88"/>
              <geom pos="0.0625 0.0784 0.0489" type="mesh" mesh="thumb_fingertip" class="visual" material="hand_gray"/>
              <geom type="mesh" mesh="white_tip_thumb" class="visual" material="hand_dark"/>
            </body>
          </body>
        </body>
      </body>
    </body>
  </worldbody>

  <contact>
    <exclude body1="palm" body2="mcp_joint"/>
    <exclude body1="palm" body2="mcp_joint_2"/>
    <exclude body1="palm" body2="mcp_joint_3"/>
    <exclude body1="palm" body2="thumb_temp_base"/>
  </contact>

  <actuator>
    <position name="act_1"  joint="1"  ctrlrange="-0.314 2.23"/>
    <position name="act_0"  joint="0"  ctrlrange="-1.047 1.047"/>
    <position name="act_2"  joint="2"  ctrlrange="-0.506 1.885"/>
    <position name="act_3"  joint="3"  ctrlrange="-0.366 2.042"/>
    <position name="act_5"  joint="5"  ctrlrange="-0.314 2.23"/>
    <position name="act_4"  joint="4"  ctrlrange="-1.047 1.047"/>
    <position name="act_6"  joint="6"  ctrlrange="-0.506 1.885"/>
    <position name="act_7"  joint="7"  ctrlrange="-0.366 2.042"/>
    <position name="act_9"  joint="9"  ctrlrange="-0.314 2.23"/>
    <position name="act_8"  joint="8"  ctrlrange="-1.047 1.047"/>
    <position name="act_10" joint="10" ctrlrange="-0.506 1.885"/>
    <position name="act_11" joint="11" ctrlrange="-0.366 2.042"/>
    <position name="act_12" joint="12" ctrlrange="-0.349 2.094"/>
    <position name="act_13" joint="13" ctrlrange="-0.47 2.443"/>
    <position name="act_14" joint="14" ctrlrange="-1.2 1.9"/>
    <position name="act_15" joint="15" ctrlrange="-1.34 1.88"/>
  </actuator>
</mujoco>
