<?xml version="1.0" encoding="utf-8"?>
<mujoco model="Dex5-URDF-L">
  <compiler angle="radian" meshdir="left/meshes"/>
  <asset>
    <mesh name="base_link00L" content_type="model/stl" file="base_link00L.STL"/>
    <mesh name="Link_11L" content_type="model/stl" file="Link_11L.STL"/>
    <mesh name="Link_12L" content_type="model/stl" file="Link_12L.STL"/>
    <mesh name="Link_13L" content_type="model/stl" file="Link_13L.STL"/>
    <mesh name="Link_14L" content_type="model/stl" file="Link_14L.STL"/>
    <mesh name="Link_21L" content_type="model/stl" file="Link_21L.STL"/>
    <mesh name="Link_22L" content_type="model/stl" file="Link_22L.STL"/>
    <mesh name="Link_23L" content_type="model/stl" file="Link_23L.STL"/>
    <mesh name="Link_24L" content_type="model/stl" file="Link_24L.STL"/>
    <mesh name="Link_31L" content_type="model/stl" file="Link_31L.STL"/>
    <mesh name="Link_32L" content_type="model/stl" file="Link_32L.STL"/>
    <mesh name="Link_33L" content_type="model/stl" file="Link_33L.STL"/>
    <mesh name="Link_34L" content_type="model/stl" file="Link_34L.STL"/>
    <mesh name="Link_41L" content_type="model/stl" file="Link_41L.STL"/>
    <mesh name="Link_42L" content_type="model/stl" file="Link_42L.STL"/>
    <mesh name="Link_43L" content_type="model/stl" file="Link_43L.STL"/>
    <mesh name="Link_44L" content_type="model/stl" file="Link_44L.STL"/>
    <mesh name="Link_51L" content_type="model/stl" file="Link_51L.STL"/>
    <mesh name="Link_52L" content_type="model/stl" file="Link_52L.STL"/>
    <mesh name="Link_53L" content_type="model/stl" file="Link_53L.STL"/>
    <mesh name="Link_54L" content_type="model/stl" file="Link_54L.STL"/>
  </asset>
  <worldbody>
    <body name="hand_root" quat="0.7071068 0.7071068 0 0">
      <geom type="mesh" contype="0" conaffinity="0" group="1" density="0" rgba="0.752941 0.752941 0.752941 0.7" mesh="base_link00L"/>
      <geom type="mesh" rgba="0.752941 0.752941 0.752941 0.7" mesh="base_link00L" contype="0" conaffinity="0"/>
      <body name="Link_11L" pos="0 0 -0.01435">
        <inertial pos="-0.008418 0.000123 -0.003247" quat="0.0170223 0.756235 0.00551611 0.654055" mass="0.02363" diaginertia="3.88743e-06 3.60721e-06 2.61432e-06"/>
        <joint name="Yaw_11L" pos="0 0 0" axis="0 0 1" range="-0.5867 0.6803" actuatorfrcrange="-0.93 0.93"/>
        <geom type="mesh" contype="0" conaffinity="0" group="1" density="0" rgba="0.752941 0.752941 0.752941 1" mesh="Link_11L"/>
        <geom type="mesh" rgba="0.752941 0.752941 0.752941 1" mesh="Link_11L" contype="0" conaffinity="0"/>
        <body name="Link_12L" pos="-1.06041e-05 0 0" quat="0.707107 0.707107 0 0">
          <inertial pos="0.014668 1.3e-05 -0.004099" quat="0.408251 0.575467 0.577544 0.410624" mass="0.015809" diaginertia="4.04972e-06 3.70479e-06 2.98874e-06"/>
          <joint name="Roll_12L" pos="0 0 0" axis="0 0 1" range="-1.8151 0" actuatorfrcrange="-0.93 0.93"/>
          <geom type="mesh" contype="0" conaffinity="0" group="1" density="0" rgba="0.752941 0.752941 0.752941 1" mesh="Link_12L"/>
          <geom type="mesh" rgba="0.752941 0.752941 0.752941 1" mesh="Link_12L" contype="0" conaffinity="0"/>
          <body name="Link_13L" pos="0.0335 0 -0.006" quat="0.707107 -0.707107 0 0">
            <inertial pos="0.018557 -0.006933 0.000159" quat="-0.0509898 0.706282 0.0461116 0.704585" mass="0.06674" diaginertia="2.3879e-05 2.31949e-05 8.83599e-06"/>
            <joint name="Pitch_13L" pos="0 0 0" axis="0 0 1" range="0 1.7652" actuatorfrcrange="-0.93 0.93"/>
            <geom type="mesh" contype="0" conaffinity="0" group="1" density="0" rgba="0.752941 0.752941 0.752941 1" mesh="Link_13L"/>
            <geom type="mesh" rgba="0.752941 0.752941 0.752941 1" mesh="Link_13L" contype="0" conaffinity="0"/>
            <body name="Link_14L" pos="0.0366088 -0.00536598 0">
              <inertial pos="0.028085 0.003322 0.000472" quat="0.472849 0.506452 0.510414 0.50931" mass="0.020073" diaginertia="6.09065e-06 5.6186e-06 1.9266e-06"/>
              <joint name="Pitch_14L" pos="0 0 0" axis="0 0 1" range="0 1.6406" actuatorfrcrange="-0.93 0.93"/>
              <geom type="mesh" contype="0" conaffinity="0" group="1" density="0" rgba="0.752941 0.752941 0.752941 1" mesh="Link_14L"/>
              <geom type="mesh" rgba="0.752941 0.752941 0.752941 1" mesh="Link_14L" contype="0" conaffinity="0"/>
            </body>
          </body>
        </body>
      </body>
      <body name="Link_21L" pos="0.01 0.0731434 0.00347022" quat="0 -0.707107 -0.707107 0">
        <inertial pos="0.007826 -5e-06 -0.004125" quat="0.286741 0.642193 0.652687 0.281721" mass="0.004497" diaginertia="1.37516e-07 1.30215e-07 5.57971e-08"/>
        <joint name="Roll_21L" pos="0 0 0" axis="0 0 1" range="-0.38397 0.38397" actuatorfrcrange="-0.93 0.93"/>
        <geom type="mesh" contype="0" conaffinity="0" group="1" density="0" rgba="0.792157 0.819608 0.933333 1" mesh="Link_21L"/>
        <geom type="mesh" rgba="0.792157 0.819608 0.933333 1" mesh="Link_21L" contype="0" conaffinity="0"/>
        <body name="Link_22L" pos="0.0042 0 0" quat="0.707107 0.707107 0 0">
          <inertial pos="0.021242 -0.005936 5.9e-05" quat="-0.014401 0.706631 0.017695 0.707214" mass="0.017982" diaginertia="4.37013e-06 4.08705e-06 1.20085e-06"/>
          <joint name="Pitch_22L" pos="0 0 0" axis="0 0 1" range="0 1.5708" actuatorfrcrange="-0.93 0.93"/>
          <geom type="mesh" contype="0" conaffinity="0" group="1" density="0" rgba="0.792157 0.819608 0.933333 1" mesh="Link_22L"/>
          <geom type="mesh" rgba="0.792157 0.819608 0.933333 1" mesh="Link_22L" contype="0" conaffinity="0"/>
          <body name="Link_23L" pos="0.04 0 0">
            <inertial pos="0.011393 -0.005777 1e-06" quat="0.27941 0.648386 -0.281286 0.649926" mass="0.012776" diaginertia="8.29432e-07 6.90028e-07 5.7959e-07"/>
            <joint name="Pitch_23L" pos="0 0 0" axis="0 0 1" range="0 1.68424" actuatorfrcrange="-0.93 0.93"/>
            <geom type="mesh" contype="0" conaffinity="0" group="1" density="0" rgba="0.792157 0.819608 0.933333 1" mesh="Link_23L"/>
            <geom type="mesh" rgba="0.792157 0.819608 0.933333 1" mesh="Link_23L" contype="0" conaffinity="0"/>
            <body name="Link_24L" pos="0.020985 0.0008043 0">
              <inertial pos="0.009354 -0.004824 7.2e-05" quat="0.468377 0.474783 0.524464 0.529285" mass="0.00639891" diaginertia="1.47892e-06 1.44823e-06 4.83167e-07"/>
              <joint name="Pitch_24L" pos="0 0 0" axis="0 0 1" range="0 1.3963" actuatorfrcrange="-0.93 0.93"/>
              <geom type="mesh" contype="0" conaffinity="0" group="1" density="0" rgba="0.792157 0.819608 0.933333 1" mesh="Link_24L"/>
              <geom type="mesh" rgba="0.792157 0.819608 0.933333 1" mesh="Link_24L" contype="0" conaffinity="0"/>
            </body>
          </body>
        </body>
      </body>
      <body name="Link_31L" pos="-0.012 0.077143 0.0034702" quat="-2.59734e-06 -0.707105 -0.707108 -2.59735e-06">
        <inertial pos="0.007826 -5e-06 -0.004125" quat="0.286741 0.642193 0.652687 0.281721" mass="0.004497" diaginertia="1.37516e-07 1.30215e-07 5.57971e-08"/>
        <joint name="Roll_31L" pos="0 0 0" axis="0 0 1" range="-0.38397 0.38397" actuatorfrcrange="-0.93 0.93"/>
        <geom type="mesh" contype="0" conaffinity="0" group="1" density="0" rgba="0.792157 0.819608 0.933333 1" mesh="Link_31L"/>
        <geom type="mesh" rgba="0.792157 0.819608 0.933333 1" mesh="Link_31L" contype="0" conaffinity="0"/>
        <body name="Link_32L" pos="0.0042 0 0" quat="0.707107 0.707107 0 0">
          <inertial pos="0.021242 -0.005936 5.9e-05" quat="-0.014401 0.706631 0.017695 0.707214" mass="0.017982" diaginertia="4.37013e-06 4.08705e-06 1.20085e-06"/>
          <joint name="Pitch_32L" pos="0 0 0" axis="0 0 1" range="0 1.5708" actuatorfrcrange="-0.93 0.93"/>
          <geom type="mesh" contype="0" conaffinity="0" group="1" density="0" rgba="0.792157 0.819608 0.933333 1" mesh="Link_32L"/>
          <geom type="mesh" rgba="0.792157 0.819608 0.933333 1" mesh="Link_32L" contype="0" conaffinity="0"/>
          <body name="Link_33L" pos="0.04 0 0">
            <inertial pos="0.011393 -0.005777 1e-06" quat="0.27941 0.648386 -0.281286 0.649926" mass="0.012776" diaginertia="8.29432e-07 6.90028e-07 5.7959e-07"/>
            <joint name="Pitch_33L" pos="0 0 0" axis="0 0 1" range="0 1.68424" actuatorfrcrange="-0.93 0.93"/>
            <geom type="mesh" contype="0" conaffinity="0" group="1" density="0" rgba="0.792157 0.819608 0.933333 1" mesh="Link_33L"/>
            <geom type="mesh" rgba="0.792157 0.819608 0.933333 1" mesh="Link_33L" contype="0" conaffinity="0"/>
            <body name="Link_34L" pos="0.020985 0.0008043 0">
              <inertial pos="0.009354 -0.004824 7.2e-05" quat="0.468377 0.474783 0.524464 0.529285" mass="0.00639891" diaginertia="1.47892e-06 1.44823e-06 4.83167e-07"/>
              <joint name="Pitch_34L" pos="0 0 0" axis="0 0 1" range="0 1.3963" actuatorfrcrange="-0.93 0.93"/>
              <geom type="mesh" contype="0" conaffinity="0" group="1" density="0" rgba="0.792157 0.819608 0.933333 1" mesh="Link_34L"/>
              <geom type="mesh" rgba="0.792157 0.819608 0.933333 1" mesh="Link_34L" contype="0" conaffinity="0"/>
            </body>
          </body>
        </body>
      </body>
      <body name="Link_41L" pos="-0.034 0.073143 0.0034702" quat="-2.59734e-06 -0.707105 -0.707108 -2.59735e-06">
        <inertial pos="0.007826 -5e-06 -0.004125" quat="0.286741 0.642193 0.652687 0.281721" mass="0.004497" diaginertia="1.37516e-07 1.30215e-07 5.57971e-08"/>
        <joint name="Link_41L" pos="0 0 0" axis="0 0 1" range="-0.38397 0.38397" actuatorfrcrange="-0.93 0.93"/>
        <geom type="mesh" contype="0" conaffinity="0" group="1" density="0" rgba="0.792157 0.819608 0.933333 1" mesh="Link_41L"/>
        <geom type="mesh" rgba="0.792157 0.819608 0.933333 1" mesh="Link_41L" contype="0" conaffinity="0"/>
        <body name="Link_42L" pos="0.0042 0 0" quat="0.707107 0.707107 0 0">
          <inertial pos="0.021242 -0.005936 5.9e-05" quat="-0.014401 0.706631 0.017695 0.707214" mass="0.017982" diaginertia="4.37013e-06 4.08705e-06 1.20085e-06"/>
          <joint name="Pitch_42L" pos="0 0 0" axis="0 0 1" range="0 1.5708" actuatorfrcrange="-0.93 0.93"/>
          <geom type="mesh" contype="0" conaffinity="0" group="1" density="0" rgba="0.792157 0.819608 0.933333 1" mesh="Link_42L"/>
          <geom type="mesh" rgba="0.792157 0.819608 0.933333 1" mesh="Link_42L" contype="0" conaffinity="0"/>
          <body name="Link_43L" pos="0.04 0 0">
            <inertial pos="0.011393 -0.005777 1e-06" quat="0.27941 0.648386 -0.281286 0.649926" mass="0.012776" diaginertia="8.29432e-07 6.90028e-07 5.7959e-07"/>
            <joint name="Pitch_43L" pos="0 0 0" axis="0 0 1" range="0 1.68424" actuatorfrcrange="-0.93 0.93"/>
            <geom type="mesh" contype="0" conaffinity="0" group="1" density="0" rgba="0.792157 0.819608 0.933333 1" mesh="Link_43L"/>
            <geom type="mesh" rgba="0.792157 0.819608 0.933333 1" mesh="Link_43L" contype="0" conaffinity="0"/>
            <body name="Link_44L" pos="0.0209846 0.000804304 0">
              <inertial pos="0.009354 -0.004824 7.2e-05" quat="0.468377 0.474783 0.524464 0.529285" mass="0.00639891" diaginertia="1.47892e-06 1.44823e-06 4.83167e-07"/>
              <joint name="Pitch_44L" pos="0 0 0" axis="0 0 1" range="0 1.3963" actuatorfrcrange="-0.93 0.93"/>
              <geom type="mesh" contype="0" conaffinity="0" group="1" density="0" rgba="0.792157 0.819608 0.933333 1" mesh="Link_44L"/>
              <geom type="mesh" rgba="0.792157 0.819608 0.933333 1" mesh="Link_44L" contype="0" conaffinity="0"/>
            </body>
          </body>
        </body>
      </body>
      <body name="Link_51L" pos="-0.056 0.0691434 0.00347022" quat="0 -0.707107 -0.707107 0">
        <inertial pos="0.007826 -5e-06 -0.004125" quat="0.286741 0.642193 0.652687 0.281721" mass="0.004497" diaginertia="1.37516e-07 1.30215e-07 5.57971e-08"/>
        <joint name="Roll_51L" pos="0 0 0" axis="0 0 1" range="-0.38397 0.38397" actuatorfrcrange="-0.93 0.93"/>
        <geom type="mesh" contype="0" conaffinity="0" group="1" density="0" rgba="0.792157 0.819608 0.933333 1" mesh="Link_51L"/>
        <geom type="mesh" rgba="0.792157 0.819608 0.933333 1" mesh="Link_51L" contype="0" conaffinity="0"/>
        <body name="Link_52L" pos="0.0042 0 0" quat="0.707107 0.707107 0 0">
          <inertial pos="0.021242 -0.005936 5.9e-05" quat="-0.014401 0.706631 0.017695 0.707214" mass="0.017982" diaginertia="4.37013e-06 4.08705e-06 1.20085e-06"/>
          <joint name="Pitch_52L" pos="0 0 0" axis="0 0 1" range="0 1.5708" actuatorfrcrange="-0.93 0.93"/>
          <geom type="mesh" contype="0" conaffinity="0" group="1" density="0" rgba="0.792157 0.819608 0.933333 1" mesh="Link_52L"/>
          <geom type="mesh" rgba="0.792157 0.819608 0.933333 1" mesh="Link_52L" contype="0" conaffinity="0"/>
          <body name="Link_53L" pos="0.04 0 0">
            <inertial pos="0.011393 -0.005777 1e-06" quat="0.27941 0.648386 -0.281286 0.649926" mass="0.012776" diaginertia="8.29432e-07 6.90028e-07 5.7959e-07"/>
            <joint name="Pitch_53L" pos="0 0 0" axis="0 0 1" range="0 1.68424" actuatorfrcrange="-0.93 0.93"/>
            <geom type="mesh" contype="0" conaffinity="0" group="1" density="0" rgba="0.792157 0.819608 0.933333 1" mesh="Link_53L"/>
            <geom type="mesh" rgba="0.792157 0.819608 0.933333 1" mesh="Link_53L" contype="0" conaffinity="0"/>
            <body name="Link_54L" pos="0.0209846 0.000804304 0">
              <inertial pos="0.009354 -0.004824 7.2e-05" quat="0.468377 0.474783 0.524464 0.529285" mass="0.00639891" diaginertia="1.47892e-06 1.44823e-06 4.83167e-07"/>
              <joint name="Pitch_54L" pos="0 0 0" axis="0 0 1" range="0 1.3963" actuatorfrcrange="-0.93 0.93"/>
              <geom type="mesh" contype="0" conaffinity="0" group="1" density="0" rgba="0.792157 0.819608 0.933333 1" mesh="Link_54L"/>
              <geom type="mesh" rgba="0.792157 0.819608 0.933333 1" mesh="Link_54L" contype="0" conaffinity="0"/>
            </body>
          </body>
        </body>
      </body>
    </body>
  </worldbody>
  <visual>
    <global offwidth="1280" offheight="720"/>
  </visual>
  <option gravity="0 0 0"/>
  <actuator>
    <position name="Yaw_11L_pos" joint="Yaw_11L" kp="5.0" ctrlrange="-0.5867 0.6803"/>
    <position name="Roll_12L_pos" joint="Roll_12L" kp="5.0" ctrlrange="-1.8151 0.0"/>
    <position name="Pitch_13L_pos" joint="Pitch_13L" kp="5.0" ctrlrange="0.0 1.7652"/>
    <position name="Pitch_14L_pos" joint="Pitch_14L" kp="5.0" ctrlrange="0.0 1.6406"/>
    <position name="Roll_21L_pos" joint="Roll_21L" kp="5.0" ctrlrange="-0.38397 0.38397"/>
    <position name="Pitch_22L_pos" joint="Pitch_22L" kp="5.0" ctrlrange="0.0 1.5708"/>
    <position name="Pitch_23L_pos" joint="Pitch_23L" kp="5.0" ctrlrange="0.0 1.684242699"/>
    <position name="Pitch_24L_pos" joint="Pitch_24L" kp="5.0" ctrlrange="0.0 1.3963"/>
    <position name="Roll_31L_pos" joint="Roll_31L" kp="5.0" ctrlrange="-0.38397 0.38397"/>
    <position name="Pitch_32L_pos" joint="Pitch_32L" kp="5.0" ctrlrange="0.0 1.5708"/>
    <position name="Pitch_33L_pos" joint="Pitch_33L" kp="5.0" ctrlrange="0.0 1.684242699"/>
    <position name="Pitch_34L_pos" joint="Pitch_34L" kp="5.0" ctrlrange="0.0 1.3963"/>
    <position name="Link_41L_pos" joint="Link_41L" kp="5.0" ctrlrange="-0.38397 0.38397"/>
    <position name="Pitch_42L_pos" joint="Pitch_42L" kp="5.0" ctrlrange="0.0 1.5708"/>
    <position name="Pitch_43L_pos" joint="Pitch_43L" kp="5.0" ctrlrange="0.0 1.684242699"/>
    <position name="Pitch_44L_pos" joint="Pitch_44L" kp="5.0" ctrlrange="0.0 1.3963"/>
    <position name="Roll_51L_pos" joint="Roll_51L" kp="5.0" ctrlrange="-0.38397 0.38397"/>
    <position name="Pitch_52L_pos" joint="Pitch_52L" kp="5.0" ctrlrange="0.0 1.5708"/>
    <position name="Pitch_53L_pos" joint="Pitch_53L" kp="5.0" ctrlrange="0.0 1.684242699"/>
    <position name="Pitch_54L_pos" joint="Pitch_54L" kp="5.0" ctrlrange="0.0 1.3963"/>
  </actuator>
</mujoco>
