<?xml version="1.0" encoding="utf-8"?>
<mujoco model="Dex5-URDF-R">
  <compiler angle="radian" meshdir="right/meshes"/>
  <asset>
    <mesh name="base_link00" content_type="model/stl" file="base_link00.STL"/>
    <mesh name="Link_11R" content_type="model/stl" file="Link_11R.STL"/>
    <mesh name="Link_12R" content_type="model/stl" file="Link_12R.STL"/>
    <mesh name="Link_13R" content_type="model/stl" file="Link_13R.STL"/>
    <mesh name="Link_14R" content_type="model/stl" file="Link_14R.STL"/>
    <mesh name="Link_21R" content_type="model/stl" file="Link_21R.STL"/>
    <mesh name="Link_22R" content_type="model/stl" file="Link_22R.STL"/>
    <mesh name="Link_23R" content_type="model/stl" file="Link_23R.STL"/>
    <mesh name="Link_24R" content_type="model/stl" file="Link_24R.STL"/>
    <mesh name="Link_31R" content_type="model/stl" file="Link_31R.STL"/>
    <mesh name="Link_32R" content_type="model/stl" file="Link_32R.STL"/>
    <mesh name="Link_33R" content_type="model/stl" file="Link_33R.STL"/>
    <mesh name="Link_34R" content_type="model/stl" file="Link_34R.STL"/>
    <mesh name="Link_41R" content_type="model/stl" file="Link_41R.STL"/>
    <mesh name="Link_42R" content_type="model/stl" file="Link_42R.STL"/>
    <mesh name="Link_43R" content_type="model/stl" file="Link_43R.STL"/>
    <mesh name="Link_44R" content_type="model/stl" file="Link_44R.STL"/>
    <mesh name="Link_51R" content_type="model/stl" file="Link_51R.STL"/>
    <mesh name="Link_52R" content_type="model/stl" file="Link_52R.STL"/>
    <mesh name="Link_53R" content_type="model/stl" file="Link_53R.STL"/>
    <mesh name="Link_54R" content_type="model/stl" file="Link_54R.STL"/>
  </asset>
  <worldbody>
    <body name="hand_root" quat="0.7071068 0.7071068 0 0">
      <geom type="mesh" contype="0" conaffinity="0" group="1" density="0" rgba="0.752941 0.752941 0.752941 0.7" mesh="base_link00"/>
      <geom type="mesh" rgba="0.752941 0.752941 0.752941 0.7" mesh="base_link00" contype="0" conaffinity="0"/>
      <body name="Link_11R" pos="0 0 0.01435">
        <inertial pos="-0.008418 0.000123 -0.003247" quat="0.0170223 0.756235 0.00551611 0.654055" mass="0.02363" diaginertia="3.88743e-06 3.60721e-06 2.61432e-06"/>
        <joint name="Yaw_11R" pos="0 0 0" axis="0 0 1" range="-0.5867 0.6803" actuatorfrcrange="-0.93 0.93"/>
        <geom type="mesh" contype="0" conaffinity="0" group="1" density="0" rgba="0.752941 0.752941 0.752941 1" mesh="Link_11R"/>
        <geom type="mesh" rgba="0.752941 0.752941 0.752941 1" mesh="Link_11R" contype="0" conaffinity="0"/>
        <body name="Link_12R" pos="-1.06041e-05 0 0" quat="0.707107 0.707107 0 0">
          <inertial pos="0.014668 1.3e-05 -0.004099" quat="0.408251 0.575467 0.577544 0.410624" mass="0.015809" diaginertia="4.04972e-06 3.70479e-06 2.98874e-06"/>
          <joint name="Roll_12R" pos="0 0 0" axis="0 0 1" range="0 1.8151" actuatorfrcrange="-0.93 0.93"/>
          <geom type="mesh" contype="0" conaffinity="0" group="1" density="0" rgba="0.752941 0.752941 0.752941 1" mesh="Link_12R"/>
          <geom type="mesh" rgba="0.752941 0.752941 0.752941 1" mesh="Link_12R" contype="0" conaffinity="0"/>
          <body name="Link_13R" pos="0.0335 0 -0.006" quat="0.707107 -0.707107 -5.48304e-06 -5.48304e-06">
            <inertial pos="0.018557 -0.006933 0.000159" quat="-0.0509898 0.706282 0.0461116 0.704585" mass="0.06674" diaginertia="2.3879e-05 2.31949e-05 8.83599e-06"/>
            <joint name="Pitch_13R" pos="0 0 0" axis="0 0 1" range="0 1.76523" actuatorfrcrange="-0.93 0.93"/>
            <geom type="mesh" contype="0" conaffinity="0" group="1" density="0" rgba="0.752941 0.752941 0.752941 1" mesh="Link_13R"/>
            <geom type="mesh" rgba="0.752941 0.752941 0.752941 1" mesh="Link_13R" contype="0" conaffinity="0"/>
            <body name="Link_14R" pos="0.036609 -0.0053654 0">
              <inertial pos="0.028085 0.003322 0.000472" quat="0.472849 0.506452 0.510414 0.50931" mass="0.020073" diaginertia="6.09065e-06 5.6186e-06 1.9266e-06"/>
              <joint name="Pitch_14R" pos="0 0 0" axis="0 0 1" range="0 1.6406" actuatorfrcrange="-0.93 0.93"/>
              <geom type="mesh" contype="0" conaffinity="0" group="1" density="0" rgba="0.752941 0.752941 0.752941 1" mesh="Link_14R"/>
              <geom type="mesh" rgba="0.752941 0.752941 0.752941 1" mesh="Link_14R" contype="0" conaffinity="0"/>
            </body>
          </body>
        </body>
      </body>
      <body name="Link_21R" pos="0.01 0.073143 -0.0034702" quat="0.707105 0 0 0.707108">
        <inertial pos="0.007826 -5e-06 -0.004125" quat="0.286741 0.642193 0.652687 0.281721" mass="0.004497" diaginertia="1.37516e-07 1.30215e-07 5.57971e-08"/>
        <joint name="Roll_21R" pos="0 0 0" axis="0 0 1" range="-0.38397 0.38397"/>
        <geom type="mesh" contype="0" conaffinity="0" group="1" density="0" rgba="0.792157 0.819608 0.933333 1" mesh="Link_21R"/>
        <geom type="mesh" rgba="0.792157 0.819608 0.933333 1" mesh="Link_21R" contype="0" conaffinity="0"/>
        <body name="Link_22R" pos="0.0042 0 0" quat="0.707107 0.707107 0 0">
          <inertial pos="0.021242 -0.005936 5.9e-05" quat="-0.014401 0.706631 0.017695 0.707214" mass="0.017982" diaginertia="4.37013e-06 4.08705e-06 1.20085e-06"/>
          <joint name="Pitch_22R" pos="0 0 0" axis="0 0 1" range="0 1.5708"/>
          <geom type="mesh" contype="0" conaffinity="0" group="1" density="0" rgba="0.792157 0.819608 0.933333 1" mesh="Link_22R"/>
          <geom type="mesh" rgba="0.792157 0.819608 0.933333 1" mesh="Link_22R" contype="0" conaffinity="0"/>
          <body name="Link_23R" pos="0.04 0 0">
            <inertial pos="0.011393 -0.005777 1e-06" quat="0.27941 0.648386 -0.281286 0.649926" mass="0.012776" diaginertia="8.29432e-07 6.90028e-07 5.7959e-07"/>
            <joint name="Pitch_23R" pos="0 0 0" axis="0 0 1" range="0 1.68424"/>
            <geom type="mesh" contype="0" conaffinity="0" group="1" density="0" rgba="0.792157 0.819608 0.933333 1" mesh="Link_23R"/>
            <geom type="mesh" rgba="0.792157 0.819608 0.933333 1" mesh="Link_23R" contype="0" conaffinity="0"/>
            <body name="Link_24R" pos="0.0209846 0.000804304 0">
              <inertial pos="0.009354 -0.004824 7.2e-05" quat="0.468377 0.474783 0.524464 0.529285" mass="0.00639891" diaginertia="1.47892e-06 1.44823e-06 4.83167e-07"/>
              <joint name="Pitch_24R" pos="0 0 0" axis="0 0 1" range="0 1.39626"/>
              <geom type="mesh" contype="0" conaffinity="0" group="1" density="0" rgba="0.792157 0.819608 0.933333 1" mesh="Link_24R"/>
              <geom type="mesh" rgba="0.792157 0.819608 0.933333 1" mesh="Link_24R" contype="0" conaffinity="0"/>
            </body>
          </body>
        </body>
      </body>
      <body name="Link_31R" pos="-0.012 0.077143 -0.0034702" quat="0.707105 0 0 0.707108">
        <inertial pos="0.007826 -5e-06 -0.004125" quat="0.286741 0.642193 0.652687 0.281721" mass="0.004497" diaginertia="1.37516e-07 1.30215e-07 5.57971e-08"/>
        <joint name="Roll_31R" pos="0 0 0" axis="0 0 1" range="-0.38397 0.38397"/>
        <geom type="mesh" contype="0" conaffinity="0" group="1" density="0" rgba="0.792157 0.819608 0.933333 1" mesh="Link_31R"/>
        <geom type="mesh" rgba="0.792157 0.819608 0.933333 1" mesh="Link_31R" contype="0" conaffinity="0"/>
        <body name="Link_32R" pos="0.0042 0 0" quat="0.707107 0.707107 0 0">
          <inertial pos="0.021242 -0.005936 5.9e-05" quat="-0.014401 0.706631 0.017695 0.707214" mass="0.017982" diaginertia="4.37013e-06 4.08705e-06 1.20085e-06"/>
          <joint name="Pitch_32R" pos="0 0 0" axis="0 0 1" range="0 1.5708"/>
          <geom type="mesh" contype="0" conaffinity="0" group="1" density="0" rgba="0.792157 0.819608 0.933333 1" mesh="Link_32R"/>
          <geom type="mesh" rgba="0.792157 0.819608 0.933333 1" mesh="Link_32R" contype="0" conaffinity="0"/>
          <body name="Link_33R" pos="0.04 0 0">
            <inertial pos="0.011393 -0.005777 1e-06" quat="0.27941 0.648386 -0.281286 0.649926" mass="0.012776" diaginertia="8.29432e-07 6.90028e-07 5.7959e-07"/>
            <joint name="Pitch_33R" pos="0 0 0" axis="0 0 1" range="0 1.68424"/>
            <geom type="mesh" contype="0" conaffinity="0" group="1" density="0" rgba="0.792157 0.819608 0.933333 1" mesh="Link_33R"/>
            <geom type="mesh" rgba="0.792157 0.819608 0.933333 1" mesh="Link_33R" contype="0" conaffinity="0"/>
            <body name="Link_34R" pos="0.0209846 0.000804304 0">
              <inertial pos="0.009354 -0.004824 7.2e-05" quat="0.468377 0.474783 0.524464 0.529285" mass="0.00639891" diaginertia="1.47892e-06 1.44823e-06 4.83167e-07"/>
              <joint name="Pitch_34R" pos="0 0 0" axis="0 0 1" range="0 1.39626"/>
              <geom type="mesh" contype="0" conaffinity="0" group="1" density="0" rgba="0.792157 0.819608 0.933333 1" mesh="Link_34R"/>
              <geom type="mesh" rgba="0.792157 0.819608 0.933333 1" mesh="Link_34R" contype="0" conaffinity="0"/>
            </body>
          </body>
        </body>
      </body>
      <body name="Link_41R" pos="-0.034 0.073143 -0.0034702" quat="0.707105 0 0 0.707108">
        <inertial pos="0.007826 -5e-06 -0.004125" quat="0.286741 0.642193 0.652687 0.281721" mass="0.004497" diaginertia="1.37516e-07 1.30215e-07 5.57971e-08"/>
        <joint name="Roll_41R" pos="0 0 0" axis="0 0 1" range="-0.38397 0.38397"/>
        <geom type="mesh" contype="0" conaffinity="0" group="1" density="0" rgba="0.792157 0.819608 0.933333 1" mesh="Link_41R"/>
        <geom type="mesh" rgba="0.792157 0.819608 0.933333 1" mesh="Link_41R" contype="0" conaffinity="0"/>
        <body name="Link_42R" pos="0.0042 0 0" quat="0.707107 0.707107 0 0">
          <inertial pos="0.021242 -0.005936 5.9e-05" quat="-0.014401 0.706631 0.017695 0.707214" mass="0.017982" diaginertia="4.37013e-06 4.08705e-06 1.20085e-06"/>
          <joint name="Pitch_42R" pos="0 0 0" axis="0 0 1" range="0 1.5708"/>
          <geom type="mesh" contype="0" conaffinity="0" group="1" density="0" rgba="0.792157 0.819608 0.933333 1" mesh="Link_42R"/>
          <geom type="mesh" rgba="0.792157 0.819608 0.933333 1" mesh="Link_42R" contype="0" conaffinity="0"/>
          <body name="Link_43R" pos="0.04 0 0">
            <inertial pos="0.011393 -0.005777 1e-06" quat="0.27941 0.648386 -0.281286 0.649926" mass="0.012776" diaginertia="8.29432e-07 6.90028e-07 5.7959e-07"/>
            <joint name="Pitch_43R" pos="0 0 0" axis="0 0 1" range="0 1.6842"/>
            <geom type="mesh" contype="0" conaffinity="0" group="1" density="0" rgba="0.792157 0.819608 0.933333 1" mesh="Link_43R"/>
            <geom type="mesh" rgba="0.792157 0.819608 0.933333 1" mesh="Link_43R" contype="0" conaffinity="0"/>
            <body name="Link_44R" pos="0.0209846 0.000804304 0">
              <inertial pos="0.009354 -0.004824 7.2e-05" quat="0.468377 0.474783 0.524464 0.529285" mass="0.00639891" diaginertia="1.47892e-06 1.44823e-06 4.83167e-07"/>
              <joint name="Pitch_44R" pos="0 0 0" axis="0 0 1" range="0 1.3963"/>
              <geom type="mesh" contype="0" conaffinity="0" group="1" density="0" rgba="0.792157 0.819608 0.933333 1" mesh="Link_44R"/>
              <geom type="mesh" rgba="0.792157 0.819608 0.933333 1" mesh="Link_44R" contype="0" conaffinity="0"/>
            </body>
          </body>
        </body>
      </body>
      <body name="Link_51R" pos="-0.056 0.0691434 -0.00347022" quat="0.707107 0 0 0.707107">
        <inertial pos="0.007826 -5e-06 -0.004125" quat="0.286741 0.642193 0.652687 0.281721" mass="0.004497" diaginertia="1.37516e-07 1.30215e-07 5.57971e-08"/>
        <joint name="Roll_51R" pos="0 0 0" axis="0 0 1" range="-0.38397 0.38397"/>
        <geom type="mesh" contype="0" conaffinity="0" group="1" density="0" rgba="0.792157 0.819608 0.933333 1" mesh="Link_51R"/>
        <geom type="mesh" rgba="0.792157 0.819608 0.933333 1" mesh="Link_51R" contype="0" conaffinity="0"/>
        <body name="Link_52R" pos="0.0042 0 0" quat="0.707107 0.707107 0 0">
          <inertial pos="0.021242 -0.005936 5.9e-05" quat="-0.014401 0.706631 0.017695 0.707214" mass="0.017982" diaginertia="4.37013e-06 4.08705e-06 1.20085e-06"/>
          <joint name="Pitch_52R" pos="0 0 0" axis="0 0 1" range="0 1.5708"/>
          <geom type="mesh" contype="0" conaffinity="0" group="1" density="0" rgba="0.792157 0.819608 0.933333 1" mesh="Link_52R"/>
          <geom type="mesh" rgba="0.792157 0.819608 0.933333 1" mesh="Link_52R" contype="0" conaffinity="0"/>
          <body name="Link_53R" pos="0.04 0 0">
            <inertial pos="0.011393 -0.005777 1e-06" quat="0.27941 0.648386 -0.281286 0.649926" mass="0.012776" diaginertia="8.29432e-07 6.90028e-07 5.7959e-07"/>
            <joint name="Pitch_53R" pos="0 0 0" axis="0 0 1" range="0 1.6842"/>
            <geom type="mesh" contype="0" conaffinity="0" group="1" density="0" rgba="0.792157 0.819608 0.933333 1" mesh="Link_53R"/>
            <geom type="mesh" rgba="0.792157 0.819608 0.933333 1" mesh="Link_53R" contype="0" conaffinity="0"/>
            <body name="Link_54R" pos="0.0209846 0.000804304 0">
              <inertial pos="0.009354 -0.004824 7.2e-05" quat="0.468377 0.474783 0.524464 0.529285" mass="0.00639891" diaginertia="1.47892e-06 1.44823e-06 4.83167e-07"/>
              <joint name="Pitch_54R" pos="0 0 0" axis="0 0 1" range="0 1.3963"/>
              <geom type="mesh" contype="0" conaffinity="0" group="1" density="0" rgba="0.792157 0.819608 0.933333 1" mesh="Link_54R"/>
              <geom type="mesh" rgba="0.792157 0.819608 0.933333 1" mesh="Link_54R" contype="0" conaffinity="0"/>
            </body>
          </body>
        </body>
      </body>
    </body>
  </worldbody>
  <visual>
    <global offwidth="1280" offheight="720"/>
  </visual>
  <option gravity="0 0 0"/>
  <actuator>
    <position name="Yaw_11R_pos" joint="Yaw_11R" kp="5.0" ctrlrange="-0.5867 0.6803"/>
    <position name="Roll_12R_pos" joint="Roll_12R" kp="5.0" ctrlrange="0.0 1.8151"/>
    <position name="Pitch_13R_pos" joint="Pitch_13R" kp="5.0" ctrlrange="0.0 1.765226"/>
    <position name="Pitch_14R_pos" joint="Pitch_14R" kp="5.0" ctrlrange="0.0 1.6406"/>
    <position name="Roll_21R_pos" joint="Roll_21R" kp="5.0" ctrlrange="-0.38397 0.38397"/>
    <position name="Pitch_22R_pos" joint="Pitch_22R" kp="5.0" ctrlrange="0.0 1.5707963"/>
    <position name="Pitch_23R_pos" joint="Pitch_23R" kp="5.0" ctrlrange="0.0 1.684242699"/>
    <position name="Pitch_24R_pos" joint="Pitch_24R" kp="5.0" ctrlrange="0.0 1.396263378"/>
    <position name="Roll_31R_pos" joint="Roll_31R" kp="5.0" ctrlrange="-0.38397 0.38397"/>
    <position name="Pitch_32R_pos" joint="Pitch_32R" kp="5.0" ctrlrange="0.0 1.5707963"/>
    <position name="Pitch_33R_pos" joint="Pitch_33R" kp="5.0" ctrlrange="0.0 1.684242699"/>
    <position name="Pitch_34R_pos" joint="Pitch_34R" kp="5.0" ctrlrange="0.0 1.396263378"/>
    <position name="Roll_41R_pos" joint="Roll_41R" kp="5.0" ctrlrange="-0.38397 0.38397"/>
    <position name="Pitch_42R_pos" joint="Pitch_42R" kp="5.0" ctrlrange="0.0 1.5708"/>
    <position name="Pitch_43R_pos" joint="Pitch_43R" kp="5.0" ctrlrange="0.0 1.6842"/>
    <position name="Pitch_44R_pos" joint="Pitch_44R" kp="5.0" ctrlrange="0.0 1.3963"/>
    <position name="Roll_51R_pos" joint="Roll_51R" kp="5.0" ctrlrange="-0.38397 0.38397"/>
    <position name="Pitch_52R_pos" joint="Pitch_52R" kp="5.0" ctrlrange="0.0 1.5708"/>
    <position name="Pitch_53R_pos" joint="Pitch_53R" kp="5.0" ctrlrange="0.0 1.6842"/>
    <position name="Pitch_54R_pos" joint="Pitch_54R" kp="5.0" ctrlrange="0.0 1.3963"/>
  </actuator>
</mujoco>
