<?xml version="1.0" encoding="utf-8"?>
<mujoco model="rohand_left">
  <compiler angle="radian" meshdir="left"/>
  <asset>
    <mesh name="base_link" content_type="model/stl" file="base_link.STL"/>
    <mesh name="if_slider_link" content_type="model/stl" file="if_slider_link.STL"/>
    <mesh name="if_slider_abpart_link" content_type="model/stl" file="if_slider_abpart_link.STL"/>
    <mesh name="if_proximal_link" content_type="model/stl" file="if_proximal_link.STL"/>
    <mesh name="if_distal_link" content_type="model/stl" file="if_distal_link.STL"/>
    <mesh name="if_connecting_link" content_type="model/stl" file="if_connecting_link.STL"/>
    <mesh name="mf_slider_link" content_type="model/stl" file="mf_slider_link.STL"/>
    <mesh name="mf_slider_abpart_link" content_type="model/stl" file="mf_slider_abpart_link.STL"/>
    <mesh name="mf_proximal_link" content_type="model/stl" file="mf_proximal_link.STL"/>
    <mesh name="mf_distal_link" content_type="model/stl" file="mf_distal_link.STL"/>
    <mesh name="mf_connecting_link" content_type="model/stl" file="mf_connecting_link.STL"/>
    <mesh name="rf_slider_link" content_type="model/stl" file="rf_slider_link.STL"/>
    <mesh name="rf_slider_abpart_link" content_type="model/stl" file="rf_slider_abpart_link.STL"/>
    <mesh name="rf_proximal_link" content_type="model/stl" file="rf_proximal_link.STL"/>
    <mesh name="rf_distal_link" content_type="model/stl" file="rf_distal_link.STL"/>
    <mesh name="rf_connecting_link" content_type="model/stl" file="rf_connecting_link.STL"/>
    <mesh name="lf_slider_link" content_type="model/stl" file="lf_slider_link.STL"/>
    <mesh name="lf_slider_abpart_link" content_type="model/stl" file="lf_slider_abpart_link.STL"/>
    <mesh name="lf_proximal_link" content_type="model/stl" file="lf_proximal_link.STL"/>
    <mesh name="lf_distal_link" content_type="model/stl" file="lf_distal_link.STL"/>
    <mesh name="lf_connecting_link" content_type="model/stl" file="lf_connecting_link.STL"/>
    <mesh name="th_root_link" content_type="model/stl" file="th_root_link.STL"/>
    <mesh name="th_proximal_link" content_type="model/stl" file="th_proximal_link.STL"/>
    <mesh name="th_slider_link" content_type="model/stl" file="th_slider_link.STL"/>
    <mesh name="th_connecting_link" content_type="model/stl" file="th_connecting_link.STL"/>
    <mesh name="th_distal_link" content_type="model/stl" file="th_distal_link.STL"/>
  </asset>
  <worldbody>
    <body name="hand_root" quat="0.7071068 0 0.7071068 0">
      <geom type="mesh" rgba="1 1 1 1" mesh="base_link" contype="0" conaffinity="0"/>
      <body name="if_slider_link" pos="-0.074396 0.026655 -0.0059032">
        <inertial pos="-0.0138319 0.00115456 1.18635e-06" quat="0.060192 0.707013 0.00166738 0.704632" mass="0.000489112" diaginertia="3.92755e-08 3.84577e-08 4.37021e-09"/>
        <joint name="if_slider_link" pos="0 0 0" axis="0.996545 -0.0830486 0" type="slide" range="0 0.019"/>
        <geom type="mesh" rgba="1 1 1 1" mesh="if_slider_link" contype="0" conaffinity="0"/>
        <body name="if_slider_abpart_link" pos="-0.02861 0.0058839 -0.00030477">
          <inertial pos="-0.0107864 -0.00263941 -0.000139132" quat="0.0598878 0.654028 0.00586955 0.754073" mass="0.000419596" diaginertia="6.31152e-09 5.74798e-09 1.64305e-09"/>
          <joint name="if_slider_abpart_link" pos="0 0 0" axis="0.0827336 0.992755 -0.0871346" range="-3.14159 3.14159" actuatorfrcrange="-1 1"/>
          <geom type="mesh" rgba="1 1 1 1" mesh="if_slider_abpart_link" contype="0" conaffinity="0"/>
        </body>
      </body>
      <body name="if_proximal_link" pos="-0.11211 0.037738 0.0020371">
        <inertial pos="-0.0180402 -0.00594319 -0.00214941" quat="0.0600774 0.713772 0.000968855 0.697796" mass="0.00154987" diaginertia="1.69645e-07 1.54805e-07 6.13282e-08"/>
        <joint name="if_proximal_link" pos="0 0 0" axis="0.0824277 0.992777 -0.0871767" range="-3.14159 3.14159" actuatorfrcrange="-1 1"/>
        <geom type="mesh" rgba="1 1 1 1" mesh="if_proximal_link" contype="0" conaffinity="0"/>
        <body name="if_distal_link" pos="-0.035776 0.0028401 -0.0014841">
          <inertial pos="-0.0242418 -0.00576634 -0.00601096" quat="0.0592789 0.620497 0.00847241 0.78192" mass="0.00422694" diaginertia="5.66687e-07 5.60884e-07 7.02818e-08"/>
          <joint name="if_distal_link" pos="0 0 0" axis="0.0824277 0.992777 -0.0871767" range="-3.14159 3.14159" actuatorfrcrange="-1 1"/>
          <geom type="mesh" rgba="1 1 1 1" mesh="if_distal_link" contype="0" conaffinity="0"/>
        </body>
      </body>
      <body name="if_connecting_link" pos="-0.11976 0.03521 0.0067299">
        <inertial pos="-0.015453 -0.0030088 -0.00700719" quat="0.625594 0.387104 0.405423 0.5426" mass="0.000197692" diaginertia="2.70716e-08 2.67093e-08 3.8339e-10"/>
        <joint name="if_connecting_link" pos="0 0 0" axis="0.0824277 0.992777 -0.0871767" range="-3.14159 3.14159" actuatorfrcrange="-1 1"/>
        <geom type="mesh" rgba="1 1 1 1" mesh="if_connecting_link" contype="0" conaffinity="0"/>
      </body>
      <body name="mf_slider_link" pos="-0.076974 0.010077 -0.0016353">
        <inertial pos="-0.0138787 0.000185328 8.62274e-08" quat="0.00459268 0.70696 -0.00459097 0.707224" mass="0.000489112" diaginertia="3.92755e-08 3.84577e-08 4.37021e-09"/>
        <joint name="mf_slider_link" pos="0 0 0" axis="0.999913 -0.013228 0.00010039" type="slide" range="0 0.019"/>
        <geom type="mesh" rgba="1 1 1 1" mesh="mf_slider_link" contype="0" conaffinity="0"/>
        <body name="mf_slider_abpart_link" pos="-0.028951 0.0038841 0">
          <inertial pos="-0.0105596 -0.00336124 -0.000727211" quat="0.00509757 0.643645 -0.00421373 0.765296" mass="0.000419596" diaginertia="6.31152e-09 5.74798e-09 1.64305e-09"/>
          <joint name="mf_slider_abpart_link" pos="0 0 0" axis="0.013228 0.999913 -7.25942e-05" range="-3.14159 3.14159" actuatorfrcrange="-1 1"/>
          <geom type="mesh" rgba="1 1 1 1" mesh="mf_slider_abpart_link" contype="0" conaffinity="0"/>
        </body>
      </body>
      <body name="mf_proximal_link" pos="-0.11587 0.017792 0.0069665">
        <inertial pos="-0.0199797 -0.00693582 -0.00446807" quat="0.00479768 0.685827 -0.00455236 0.727735" mass="0.00189509" diaginertia="2.46802e-07 2.34074e-07 7.71833e-08"/>
        <joint name="mf_proximal_link" pos="0 0 0" axis="0.013244 0.999912 4.26991e-05" range="-3.14159 3.14159" actuatorfrcrange="-1 1"/>
        <geom type="mesh" rgba="1 1 1 1" mesh="mf_proximal_link" contype="0" conaffinity="0"/>
        <body name="mf_distal_link" pos="-0.040851 0.00054126 -0.0035367">
          <inertial pos="-0.0237385 -0.00688494 -0.00679221" quat="0.00502021 0.618054 -0.00414662 0.786109" mass="0.00422696" diaginertia="5.66693e-07 5.6089e-07 7.02817e-08"/>
          <joint name="mf_distal_link" pos="0 0 0" axis="0.013244 0.999912 2.1055e-05" range="-3.14159 3.14159" actuatorfrcrange="-1 1"/>
          <geom type="mesh" rgba="1 1 1 1" mesh="mf_distal_link" contype="0" conaffinity="0"/>
        </body>
      </body>
      <body name="mf_connecting_link" pos="-0.12334 0.014341 0.011366">
        <inertial pos="-0.0173259 -0.00342061 -0.00839514" quat="0.590236 0.397798 0.392552 0.582478" mass="0.000216185" diaginertia="3.85121e-08 3.81382e-08 3.97001e-10"/>
        <joint name="mf_connecting_link" pos="0 0 0" axis="0.013244 0.999912 2.1054e-05" range="-3.14159 3.14159" actuatorfrcrange="-1 1"/>
        <geom type="mesh" rgba="1 1 1 1" mesh="mf_connecting_link" contype="0" conaffinity="0"/>
      </body>
      <body name="rf_slider_link" pos="-0.074498 -0.0072492 -0.0023801">
        <inertial pos="-0.0138579 -0.000783242 1.59406e-07" quat="-0.0200914 0.706691 0.020084 0.706951" mass="0.000489112" diaginertia="3.92755e-08 3.84577e-08 4.37021e-09"/>
        <joint name="rf_slider_link" pos="0 0 0" axis="0.9984 0.056554 9.5082e-05" type="slide" range="0 0.019"/>
        <geom type="mesh" rgba="1 1 1 1" mesh="rf_slider_link" contype="0" conaffinity="0"/>
        <body name="rf_slider_abpart_link" pos="-0.029152 0.0018551 0">
          <inertial pos="-0.0103067 -0.00409005 -0.000613628" quat="-0.0215118 0.647542 0.0183709 0.761505" mass="0.000419596" diaginertia="6.31152e-09 5.74798e-09 1.64305e-09"/>
          <joint name="rf_slider_abpart_link" pos="0 0 0" axis="-0.056554 0.9984 -7.942e-05" range="-3.14159 3.14159" actuatorfrcrange="-1 1"/>
          <geom type="mesh" rgba="1 1 1 1" mesh="rf_slider_abpart_link" contype="0" conaffinity="0"/>
        </body>
      </body>
      <body name="rf_proximal_link" pos="-0.11364 -0.0022565 0.0062163">
        <inertial pos="-0.0169549 -0.00817222 -0.00333738" quat="-0.020162 0.702396 0.0198371 0.711224" mass="0.00154985" diaginertia="1.69644e-07 1.54805e-07 6.13273e-08"/>
        <joint name="rf_proximal_link" pos="0 0 0" axis="-0.0565799 0.998398 2.102e-05" range="-3.14159 3.14159" actuatorfrcrange="-1 1"/>
        <geom type="mesh" rgba="1 1 1 1" mesh="rf_proximal_link" contype="0" conaffinity="0"/>
        <body name="rf_distal_link" pos="-0.035766 -0.0020268 -0.0026198">
          <inertial pos="-0.0226961 -0.00849649 -0.00835479" quat="-0.0229512 0.591246 0.0167376 0.805991" mass="0.00422731" diaginertia="5.6681e-07 5.61004e-07 7.02849e-08"/>
          <joint name="rf_distal_link" pos="0 0 0" axis="-0.0565799 0.998398 2.102e-05" range="-3.14159 3.14159" actuatorfrcrange="-1 1"/>
          <geom type="mesh" rgba="1 1 1 1" mesh="rf_distal_link" contype="0" conaffinity="0"/>
        </body>
      </body>
      <body name="rf_connecting_link" pos="-0.11723 -0.027174 0.008365">
        <inertial pos="-0.0182151 0.0164707 -0.00574283" quat="0.577134 0.372326 0.394011 0.610774" mass="0.000197692" diaginertia="2.70716e-08 2.67093e-08 3.8339e-10"/>
        <joint name="rf_connecting_link" pos="0 0 0" axis="-0.0565799 0.998398 2.102e-05" range="-3.14159 3.14159" actuatorfrcrange="-1 1"/>
        <geom type="mesh" rgba="1 1 1 1" mesh="rf_connecting_link" contype="0" conaffinity="0"/>
      </body>
      <body name="lf_slider_link" pos="-0.070847 -0.024182 -0.0048997">
        <inertial pos="-0.0144168 -0.00171206 3.81353e-07" quat="-0.0725352 0.706886 0.0111576 0.70351" mass="0.000510663" diaginertia="3.93663e-08 3.84683e-08 4.46095e-09"/>
        <joint name="lf_slider_link" pos="0 0 0" axis="0.99301 0.11803 8.2704e-05" type="slide" range="0 0.019"/>
        <geom type="mesh" rgba="1 1 1 1" mesh="lf_slider_link" contype="0" conaffinity="0"/>
        <body name="lf_slider_abpart_link" pos="-0.029209 4.0116e-05 0.00030326">
          <inertial pos="-0.0100358 -0.00463982 -0.00104236" quat="-0.0731706 0.643441 0.00460874 0.761977" mass="0.000419596" diaginertia="6.31152e-09 5.74798e-09 1.64305e-09"/>
          <joint name="lf_slider_abpart_link" pos="0 0 0" axis="-0.11759 0.989231 0.0871501" range="-3.14159 3.14159" actuatorfrcrange="-1 1"/>
          <geom type="mesh" rgba="1 1 1 1" mesh="lf_slider_abpart_link" contype="0" conaffinity="0"/>
        </body>
      </body>
      <body name="lf_proximal_link" pos="-0.11032 -0.022406 0.0042916">
        <inertial pos="-0.0146179 -0.00865933 -0.00404765" quat="-0.0727143 0.691913 0.00948564 0.718247" mass="0.00136661" diaginertia="1.27486e-07 1.1281e-07 5.56888e-08"/>
        <joint name="lf_proximal_link" pos="0 0 0" axis="-0.117591 0.989235 0.0871064" range="-3.14159 3.14159" actuatorfrcrange="-1 1"/>
        <geom type="mesh" rgba="1 1 1 1" mesh="lf_proximal_link" contype="0" conaffinity="0"/>
        <body name="lf_distal_link" pos="-0.031562 -0.0034532 -0.003392">
          <inertial pos="-0.0143708 -0.00839025 -0.00657796" quat="-0.0786088 0.577787 -0.00499896 0.812378" mass="0.00262043" diaginertia="1.58796e-07 1.52851e-07 3.73336e-08"/>
          <joint name="lf_distal_link" pos="0 0 0" axis="-0.117591 0.989235 0.0871064" range="-3.14159 3.14159" actuatorfrcrange="-1 1"/>
          <geom type="mesh" rgba="1 1 1 1" mesh="lf_distal_link" contype="0" conaffinity="0"/>
        </body>
      </body>
      <body name="lf_connecting_link" pos="-0.11723 -0.027174 0.008365">
        <inertial pos="-0.0121624 -0.00439577 -0.00839995" quat="0.554936 0.365025 0.354446 0.658157" mass="0.000176981" diaginertia="2.00918e-08 1.97697e-08 3.40918e-10"/>
        <joint name="lf_connecting_link" pos="0 0 0" axis="-0.11759 0.989237 0.0870847" range="-3.14159 3.14159" actuatorfrcrange="-1 1"/>
        <geom type="mesh" rgba="1 1 1 1" mesh="lf_connecting_link" contype="0" conaffinity="0"/>
      </body>
      <body name="th_root_link" pos="-0.024656 0.019554 -0.018266">
        <inertial pos="-0.0182056 0.00620278 -0.00602505" quat="0.695238 0.585521 0.173557 0.379061" mass="0.00217782" diaginertia="2.76915e-07 2.31601e-07 1.06288e-07"/>
        <joint name="th_root_link" pos="0 0 0" axis="-0.976159 0.01293 -0.21667" range="0 1.57"/>
        <geom type="mesh" rgba="1 1 1 1" mesh="th_root_link" contype="0" conaffinity="0"/>
        <body name="th_proximal_link" pos="-0.025097 0.021667 -0.015581" quat="0.779983 0.0100188 0.625595 0.0124926">
          <inertial pos="-0.00770019 0.0117883 -0.0170645" quat="0.967507 0.252845 2.21786e-06 -8.48662e-06" mass="0.00501319" diaginertia="2.07793e-06 1.88842e-06 2.93872e-07"/>
          <joint name="th_proximal_link" pos="0 0 0" axis="1 0 0" range="-3.14159 3.14159" actuatorfrcrange="-1 1"/>
          <geom type="mesh" rgba="1 1 1 1" mesh="th_proximal_link" contype="0" conaffinity="0"/>
          <body name="th_slider_link" pos="-0.0077 0.0027693 -0.00023667" quat="0.779982 -0.0100211 -0.625597 -0.012494">
            <inertial pos="-0.0119352 0.00825053 -0.00238382" quat="0.660088 0.616109 0.219646 0.369389" mass="0.000966919" diaginertia="7.86108e-08 6.04675e-08 2.46843e-08"/>
            <joint name="th_slider_link" pos="0 0 0" axis="-0.76198 0.63028 -0.14877" type="slide" range="0 0.01"/>
            <geom type="mesh" rgba="1 1 1 1" mesh="th_slider_link" contype="0" conaffinity="0"/>
            <body name="th_connecting_link" pos="-0.027697 0.024088 -0.010084">
              <inertial pos="-0.00506958 0.00225299 0.00365192" quat="0.627176 0.564628 0.301015 0.444112" mass="0.000334844" diaginertia="5.69883e-09 5.07523e-09 2.2093e-09"/>
              <joint name="th_connecting_link" pos="0 0 0" axis="0.21699 0.0320289 -0.975648" range="-3.14159 3.14159" actuatorfrcrange="-1 1"/>
              <geom type="mesh" rgba="1 1 1 1" mesh="th_connecting_link" contype="0" conaffinity="0"/>
            </body>
          </body>
          <body name="th_distal_link" pos="-0.00010351 0.023735 -0.046849" quat="0.779982 -0.0100211 -0.625597 -0.012494">
            <inertial pos="-0.00470322 0.0108132 0.00709251" quat="0.688197 0.670833 0.101841 0.256898" mass="0.00509494" diaginertia="3.08169e-07 2.4136e-07 1.68165e-07"/>
            <joint name="th_distal_link" pos="0 0 0" axis="0.21698 0.032029 -0.97565" range="-3.14159 3.14159" actuatorfrcrange="-1 1"/>
            <geom type="mesh" rgba="1 1 1 1" mesh="th_distal_link" contype="0" conaffinity="0"/>
          </body>
        </body>
      </body>
    </body>
  </worldbody>
  <visual>
    <global offwidth="1280" offheight="720"/>
  </visual>
  <option gravity="0 0 0"/>
  <actuator>
    <position name="if_slider_link_pos" joint="if_slider_link" kp="2.0" ctrlrange="0.0 0.019"/>
    <position name="if_slider_abpart_link_pos" joint="if_slider_abpart_link" kp="2.0" ctrlrange="-3.14159 3.14159"/>
    <position name="if_proximal_link_pos" joint="if_proximal_link" kp="2.0" ctrlrange="-3.14159 3.14159"/>
    <position name="if_distal_link_pos" joint="if_distal_link" kp="2.0" ctrlrange="-3.14159 3.14159"/>
    <position name="if_connecting_link_pos" joint="if_connecting_link" kp="2.0" ctrlrange="-3.14159 3.14159"/>
    <position name="mf_slider_link_pos" joint="mf_slider_link" kp="2.0" ctrlrange="0.0 0.019"/>
    <position name="mf_slider_abpart_link_pos" joint="mf_slider_abpart_link" kp="2.0" ctrlrange="-3.14159 3.14159"/>
    <position name="mf_proximal_link_pos" joint="mf_proximal_link" kp="2.0" ctrlrange="-3.14159 3.14159"/>
    <position name="mf_distal_link_pos" joint="mf_distal_link" kp="2.0" ctrlrange="-3.14159 3.14159"/>
    <position name="mf_connecting_link_pos" joint="mf_connecting_link" kp="2.0" ctrlrange="-3.14159 3.14159"/>
    <position name="rf_slider_link_pos" joint="rf_slider_link" kp="2.0" ctrlrange="0.0 0.019"/>
    <position name="rf_slider_abpart_link_pos" joint="rf_slider_abpart_link" kp="2.0" ctrlrange="-3.14159 3.14159"/>
    <position name="rf_proximal_link_pos" joint="rf_proximal_link" kp="2.0" ctrlrange="-3.14159 3.14159"/>
    <position name="rf_distal_link_pos" joint="rf_distal_link" kp="2.0" ctrlrange="-3.14159 3.14159"/>
    <position name="rf_connecting_link_pos" joint="rf_connecting_link" kp="2.0" ctrlrange="-3.14159 3.14159"/>
    <position name="lf_slider_link_pos" joint="lf_slider_link" kp="2.0" ctrlrange="0.0 0.019"/>
    <position name="lf_slider_abpart_link_pos" joint="lf_slider_abpart_link" kp="2.0" ctrlrange="-3.14159 3.14159"/>
    <position name="lf_proximal_link_pos" joint="lf_proximal_link" kp="2.0" ctrlrange="-3.14159 3.14159"/>
    <position name="lf_distal_link_pos" joint="lf_distal_link" kp="2.0" ctrlrange="-3.14159 3.14159"/>
    <position name="lf_connecting_link_pos" joint="lf_connecting_link" kp="2.0" ctrlrange="-3.14159 3.14159"/>
    <position name="th_root_link_pos" joint="th_root_link" kp="2.0" ctrlrange="0.0 1.57"/>
    <position name="th_proximal_link_pos" joint="th_proximal_link" kp="2.0" ctrlrange="-3.14159 3.14159"/>
    <position name="th_slider_link_pos" joint="th_slider_link" kp="2.0" ctrlrange="0.0 0.01"/>
    <position name="th_connecting_link_pos" joint="th_connecting_link" kp="2.0" ctrlrange="-3.14159 3.14159"/>
    <position name="th_distal_link_pos" joint="th_distal_link" kp="2.0" ctrlrange="-3.14159 3.14159"/>
  </actuator>
</mujoco>
