<?xml version="1.0" encoding="utf-8"?>
<mujoco model="rohand_right">
  <compiler angle="radian" meshdir="right"/>
  <asset>
    <mesh name="base_link" content_type="model/stl" file="base_link.STL"/>
    <mesh name="if_slider_link" content_type="model/stl" file="if_slider_link.STL"/>
    <mesh name="if_slider_abpart_link" content_type="model/stl" file="if_slider_abpart_link.STL"/>
    <mesh name="if_proximal_link" content_type="model/stl" file="if_proximal_link.STL"/>
    <mesh name="if_distal_link" content_type="model/stl" file="if_distal_link.STL"/>
    <mesh name="if_connecting_link" content_type="model/stl" file="if_connecting_link.STL"/>
    <mesh name="mf_slider_link" content_type="model/stl" file="mf_slider_link.STL"/>
    <mesh name="mf_slider_abpart_link" content_type="model/stl" file="mf_slider_abpart_link.STL"/>
    <mesh name="mf_proximal_link" content_type="model/stl" file="mf_proximal_link.STL"/>
    <mesh name="mf_distal_link" content_type="model/stl" file="mf_distal_link.STL"/>
    <mesh name="mf_connecting_link" content_type="model/stl" file="mf_connecting_link.STL"/>
    <mesh name="rf_slider_link" content_type="model/stl" file="rf_slider_link.STL"/>
    <mesh name="rf_slider_abpart_link" content_type="model/stl" file="rf_slider_abpart_link.STL"/>
    <mesh name="rf_proximal_link" content_type="model/stl" file="rf_proximal_link.STL"/>
    <mesh name="rf_distal_link" content_type="model/stl" file="rf_distal_link.STL"/>
    <mesh name="rf_connecting_link" content_type="model/stl" file="rf_connecting_link.STL"/>
    <mesh name="lf_slider_link" content_type="model/stl" file="lf_slider_link.STL"/>
    <mesh name="lf_slider_abpart_link" content_type="model/stl" file="lf_slider_abpart_link.STL"/>
    <mesh name="lf_proximal_link" content_type="model/stl" file="lf_proximal_link.STL"/>
    <mesh name="lf_distal_link" content_type="model/stl" file="lf_distal_link.STL"/>
    <mesh name="lf_connecting_link" content_type="model/stl" file="lf_connecting_link.STL"/>
    <mesh name="th_root_link" content_type="model/stl" file="th_root_link.STL"/>
    <mesh name="th_proximal_link" content_type="model/stl" file="th_proximal_link.STL"/>
    <mesh name="th_slider_link" content_type="model/stl" file="th_slider_link.STL"/>
    <mesh name="th_connecting_link" content_type="model/stl" file="th_connecting_link.STL"/>
    <mesh name="th_distal_link" content_type="model/stl" file="th_distal_link.STL"/>
  </asset>
  <worldbody>
    <body name="hand_root" quat="0.7071068 0 0.7071068 0">
      <geom type="mesh" rgba="1 1 1 1" mesh="base_link" contype="0" conaffinity="0"/>
      <body name="if_slider_link" pos="-0.074396 -0.026655 -0.0059032">
        <inertial pos="-0.0138318 -0.00115448 1.0278e-06" quat="-0.0600476 0.707008 -0.00153027 0.70465" mass="0.000489138" diaginertia="3.92779e-08 3.84609e-08 4.37013e-09"/>
        <joint name="if_slider_link" pos="0 0 0" axis="0.996545 0.0830486 0" type="slide" range="0 0.019"/>
        <geom type="mesh" rgba="1 1 1 1" mesh="if_slider_link" contype="0" conaffinity="0"/>
        <body name="if_slider_abpart_link" pos="-0.029189 0.0010654 0.00030518">
          <inertial pos="-0.00954721 -0.00427267 -0.000544594" quat="-0.059867 0.654029 -0.0058836 0.754073" mass="0.000526636" diaginertia="6.57501e-09 5.76677e-09 1.90654e-09"/>
          <joint name="if_slider_abpart_link" pos="0 0 0" axis="-0.0827336 0.992755 0.0871346" range="-3.14159 3.14159" actuatorfrcrange="-1 1"/>
          <geom type="mesh" rgba="1 1 1 1" mesh="if_slider_abpart_link" contype="0" conaffinity="0"/>
        </body>
      </body>
      <body name="if_proximal_link" pos="-0.11324 -0.024137 0.0032314">
        <inertial pos="-0.016912 -0.00765749 -0.00334237" quat="-0.0599383 0.713749 -0.000859518 0.697832" mass="0.00154953" diaginertia="1.69636e-07 1.54789e-07 6.13114e-08"/>
        <joint name="if_proximal_link" pos="0 0 0" axis="-0.0824277 0.992777 0.0871767" range="-3.14159 3.14159" actuatorfrcrange="-1 1"/>
        <geom type="mesh" rgba="1 1 1 1" mesh="if_proximal_link" contype="0" conaffinity="0"/>
        <body name="if_distal_link" pos="-0.035776 -0.0028401 -0.0014841">
          <inertial pos="-0.0201375 -0.0076584 -0.00662951" quat="-0.0593374 0.620487 -0.00853236 0.781922" mass="0.00486632" diaginertia="5.74583e-07 5.61446e-07 7.8092e-08"/>
          <joint name="if_distal_link" pos="0 0 0" axis="-0.0824277 0.992777 0.0871767" range="-3.14159 3.14159" actuatorfrcrange="-1 1"/>
          <geom type="mesh" rgba="1 1 1 1" mesh="if_distal_link" contype="0" conaffinity="0"/>
        </body>
      </body>
      <body name="if_connecting_link" pos="-0.12029 -0.028806 0.0072922">
        <inertial pos="-0.0149214 -0.00339461 -0.00756951" quat="0.5426 0.405423 0.387104 0.625594" mass="0.000197689" diaginertia="2.70715e-08 2.67091e-08 3.8339e-10"/>
        <joint name="if_connecting_link" pos="0 0 0" axis="-0.0824277 0.992777 0.0871767" range="-3.14159 3.14159" actuatorfrcrange="-1 1"/>
        <geom type="mesh" rgba="1 1 1 1" mesh="if_connecting_link" contype="0" conaffinity="0"/>
      </body>
      <body name="mf_slider_link" pos="-0.076974 -0.010077 -0.0016353">
        <inertial pos="-0.0138786 -0.00018527 -7.69159e-08" quat="-0.0045896 0.706954 0.0045878 0.70723" mass="0.000489138" diaginertia="3.92779e-08 3.84609e-08 4.37013e-09"/>
        <joint name="mf_slider_link" pos="0 0 0" axis="0.999913 0.013228 0.00010039" type="slide" range="0 0.019"/>
        <geom type="mesh" rgba="1 1 1 1" mesh="mf_slider_link" contype="0" conaffinity="0"/>
        <body name="mf_slider_abpart_link" pos="-0.029044 0.0031153 0">
          <inertial pos="-0.00981195 -0.00362935 -0.000504859" quat="-0.00509235 0.643645 0.00421773 0.765295" mass="0.000526636" diaginertia="6.57501e-09 5.76677e-09 1.90654e-09"/>
          <joint name="mf_slider_abpart_link" pos="0 0 0" axis="-0.013228 0.999913 7.25942e-05" range="-3.14159 3.14159" actuatorfrcrange="-1 1"/>
          <geom type="mesh" rgba="1 1 1 1" mesh="mf_slider_abpart_link" contype="0" conaffinity="0"/>
        </body>
      </body>
      <body name="mf_proximal_link" pos="-0.11605 -0.0040932 0.0069659">
        <inertial pos="-0.0197979 -0.00676309 -0.00446755" quat="-0.00479228 0.685827 0.00455406 0.727734" mass="0.00189502" diaginertia="2.46791e-07 2.34066e-07 7.71816e-08"/>
        <joint name="mf_proximal_link" pos="0 0 0" axis="-0.013244 0.999912 -4.26991e-05" range="-3.14159 3.14159" actuatorfrcrange="-1 1"/>
        <geom type="mesh" rgba="1 1 1 1" mesh="mf_proximal_link" contype="0" conaffinity="0"/>
        <body name="mf_distal_link" pos="-0.040851 -0.00054126 -0.0035364">
          <inertial pos="-0.02058 -0.00679451 -0.00619599" quat="-0.00506217 0.618045 0.00410755 0.786116" mass="0.00486611" diaginertia="5.7452e-07 5.61384e-07 7.80913e-08"/>
          <joint name="mf_distal_link" pos="0 0 0" axis="-0.013244 0.999912 -2.1055e-05" range="-3.14159 3.14159" actuatorfrcrange="-1 1"/>
          <geom type="mesh" rgba="1 1 1 1" mesh="mf_distal_link" contype="0" conaffinity="0"/>
        </body>
      </body>
      <body name="mf_connecting_link" pos="-0.12342 -0.0078912 0.011366">
        <inertial pos="-0.0172404 -0.00302882 -0.00839495" quat="0.582478 0.392552 0.397798 0.590236" mass="0.000216186" diaginertia="3.8512e-08 3.81381e-08 3.96995e-10"/>
        <joint name="mf_connecting_link" pos="0 0 0" axis="-0.013244 0.999912 -2.1054e-05" range="-3.14159 3.14159" actuatorfrcrange="-1 1"/>
        <geom type="mesh" rgba="1 1 1 1" mesh="mf_connecting_link" contype="0" conaffinity="0"/>
      </body>
      <body name="rf_slider_link" pos="-0.074498 0.0072492 -0.0023801">
        <inertial pos="-0.0138577 0.000783292 -2.57947e-09" quat="0.0200948 0.706685 -0.020087 0.706958" mass="0.000489138" diaginertia="3.92779e-08 3.84609e-08 4.37013e-09"/>
        <joint name="rf_slider_link" pos="0 0 0" axis="0.9984 -0.056554 9.5082e-05" type="slide" range="0 0.019"/>
        <geom type="mesh" rgba="1 1 1 1" mesh="rf_slider_link" contype="0" conaffinity="0"/>
        <body name="rf_slider_abpart_link" pos="-0.028756 0.0051336 0">
          <inertial pos="-0.0100461 -0.00293581 -0.00039841" quat="0.0215166 0.647552 -0.018367 0.761496" mass="0.000526636" diaginertia="6.57501e-09 5.76677e-09 1.90654e-09"/>
          <joint name="rf_slider_abpart_link" pos="0 0 0" axis="0.056554 0.9984 7.942e-05" range="-3.14159 3.14159" actuatorfrcrange="-1 1"/>
          <geom type="mesh" rgba="1 1 1 1" mesh="rf_slider_abpart_link" contype="0" conaffinity="0"/>
        </body>
      </body>
      <body name="rf_proximal_link" pos="-0.11287 0.015935 0.0062161">
        <inertial pos="-0.017731 -0.0055052 -0.00333587" quat="0.0203011 0.702374 -0.0197309 0.711245" mass="0.00154953" diaginertia="1.69636e-07 1.5479e-07 6.13116e-08"/>
        <joint name="rf_proximal_link" pos="0 0 0" axis="0.0565799 0.998398 -2.102e-05" range="-3.14159 3.14159" actuatorfrcrange="-1 1"/>
        <geom type="mesh" rgba="1 1 1 1" mesh="rf_proximal_link" contype="0" conaffinity="0"/>
        <body name="rf_distal_link" pos="-0.035766 0.0020268 -0.0026198">
          <inertial pos="-0.0205453 -0.0053675 -0.00756098" quat="0.0229178 0.591241 -0.0167617 0.805995" mass="0.00486608" diaginertia="5.74506e-07 5.61368e-07 7.8092e-08"/>
          <joint name="rf_distal_link" pos="0 0 0" axis="0.0565799 0.998398 -2.102e-05" range="-3.14159 3.14159" actuatorfrcrange="-1 1"/>
          <geom type="mesh" rgba="1 1 1 1" mesh="rf_distal_link" contype="0" conaffinity="0"/>
        </body>
      </body>
      <body name="rf_connecting_link" pos="-0.120485 0.0126605 0.0106154">
        <inertial pos="-0.0149582 -0.00195701 -0.00799324" quat="0.610774 0.394011 0.372326 0.577133" mass="0.000197689" diaginertia="2.70715e-08 2.67091e-08 3.8339e-10"/>
        <joint name="rf_connecting_link" pos="0 0 0" axis="0.0565797 0.998398 -2.10198e-05" range="-3.14159 3.14159" actuatorfrcrange="-1 1"/>
        <geom type="mesh" rgba="1 1 1 1" mesh="rf_connecting_link" contype="0" conaffinity="0"/>
      </body>
      <body name="lf_slider_link" pos="-0.0708466 0.0241824 -0.00489967">
        <inertial pos="-0.013783 0.00163674 3.10003e-07" quat="0.0726697 0.706881 -0.0110278 0.703503" mass="0.000489138" diaginertia="3.92779e-08 3.84609e-08 4.37013e-09"/>
        <joint name="lf_slider_link" pos="0 0 0" axis="0.99301 -0.118033 8.27045e-05" type="slide" range="0 0.019"/>
        <geom type="mesh" rgba="1 1 1 1" mesh="lf_slider_link" contype="0" conaffinity="0"/>
        <body name="lf_slider_abpart_link" pos="-0.0283858 0.0068845 -0.000306788">
          <inertial pos="-0.0102064 -0.0023426 -0.000209526" quat="0.0731498 0.643444 -0.00457337 0.761976" mass="0.000526636" diaginertia="6.57501e-09 5.76677e-09 1.90654e-09"/>
          <joint name="lf_slider_abpart_link" pos="0 0 0" axis="0.117591 0.989231 -0.08715" range="-3.14159 3.14159" actuatorfrcrange="-1 1"/>
          <geom type="mesh" rgba="1 1 1 1" mesh="lf_slider_abpart_link" contype="0" conaffinity="0"/>
        </body>
      </body>
      <body name="lf_proximal_link" pos="-0.108711 0.0359584 0.00309824">
        <inertial pos="-0.0162289 -0.00489296 -0.00285462" quat="0.0727719 0.691913 -0.00944149 0.718242" mass="0.00136678" diaginertia="1.27497e-07 1.1282e-07 5.56945e-08"/>
        <joint name="lf_proximal_link" pos="0 0 0" axis="0.117591 0.989234 -0.0871064" range="-3.14159 3.14159" actuatorfrcrange="-1 1"/>
        <geom type="mesh" rgba="1 1 1 1" mesh="lf_proximal_link" contype="0" conaffinity="0"/>
        <body name="lf_distal_link" pos="-0.031562 0.0034532 -0.003392">
          <inertial pos="-0.0131614 -0.00544871 -0.00463526" quat="0.0733114 0.577387 0.00152047 0.813171" mass="0.00327" diaginertia="1.66928e-07 1.53544e-07 4.54432e-08"/>
          <joint name="lf_distal_link" pos="0 0 0" axis="0.117591 0.989235 -0.0871064" range="-3.14159 3.14159" actuatorfrcrange="-1 1"/>
          <geom type="mesh" rgba="1 1 1 1" mesh="lf_distal_link" contype="0" conaffinity="0"/>
        </body>
      </body>
      <body name="lf_connecting_link" pos="-0.11647 0.033555 0.0078033">
        <inertial pos="-0.0129209 -0.0019848 -0.00783824" quat="0.658157 0.354446 0.365025 0.554936" mass="0.000176982" diaginertia="2.00918e-08 1.97697e-08 3.40912e-10"/>
        <joint name="lf_connecting_link" pos="0 0 0" axis="0.11759 0.989237 -0.0870847" range="-3.14159 3.14159" actuatorfrcrange="-1 1"/>
        <geom type="mesh" rgba="1 1 1 1" mesh="lf_connecting_link" contype="0" conaffinity="0"/>
      </body>
      <body name="th_root_link" pos="-0.024656 -0.019554 -0.018266">
        <inertial pos="-0.0182056 -0.00620278 -0.00602505" quat="0.379061 0.173557 0.585521 0.695238" mass="0.00217782" diaginertia="2.76915e-07 2.31601e-07 1.06288e-07"/>
        <joint name="th_root_link" pos="0 0 0" axis="0.976159 0.01293 0.21667" range="0 1.57"/>
        <geom type="mesh" rgba="1 1 1 1" mesh="th_root_link" contype="0" conaffinity="0"/>
        <body name="th_proximal_link" pos="-0.025097 -0.021667 -0.015581">
          <inertial pos="-0.0184116 -0.0115354 0.00417629" quat="-0.146061 0.608385 0.207004 0.75212" mass="0.00501308" diaginertia="2.07812e-06 1.88848e-06 2.93843e-07"/>
          <joint name="th_proximal_link" pos="0 0 0" axis="-0.21699 -0.0320289 0.975648" range="-3.14159 3.14159" actuatorfrcrange="-1 1"/>
          <geom type="mesh" rgba="1 1 1 1" mesh="th_proximal_link" contype="0" conaffinity="0"/>
          <body name="th_slider_link" pos="-0.0053401 -0.0053494 0.0068801">
            <inertial pos="-0.0085161 -0.00542249 -0.00171626" quat="0.369388 0.219642 0.616109 0.66009" mass="0.000966928" diaginertia="7.86116e-08 6.04686e-08 2.46847e-08"/>
            <joint name="th_slider_link" pos="0 0 0" axis="-0.76198 -0.63028 -0.14877" type="slide" range="0 0.01"/>
            <geom type="mesh" rgba="1 1 1 1" mesh="th_slider_link" contype="0" conaffinity="0"/>
            <body name="th_connecting_link" pos="-0.026144 -0.020984 -0.0010258">
              <inertial pos="-0.00136684 -0.00145248 -0.00439754" quat="0.444078 0.301073 0.564623 0.627177" mass="0.000607798" diaginertia="7.50727e-09 5.28315e-09 4.01801e-09"/>
              <joint name="th_connecting_link" pos="0 0 0" axis="-0.21699 0.0320289 0.975648" range="-3.14159 3.14159" actuatorfrcrange="-1 1"/>
              <geom type="mesh" rgba="1 1 1 1" mesh="th_connecting_link" contype="0" conaffinity="0"/>
            </body>
          </body>
          <body name="th_distal_link" pos="-0.049076 -0.023254 0.004868">
            <inertial pos="-0.000439995 -0.0101523 -0.00690883" quat="0.670795 0.688235 -0.256896 -0.101837" mass="0.00601773" diaginertia="3.24886e-07 2.42046e-07 1.84884e-07"/>
            <joint name="th_distal_link" pos="0 0 0" axis="-0.21698 0.032029 0.97565" range="-3.14159 3.14159" actuatorfrcrange="-1 1"/>
            <geom type="mesh" rgba="1 1 1 1" mesh="th_distal_link" contype="0" conaffinity="0"/>
          </body>
        </body>
      </body>
    </body>
  </worldbody>
  <visual>
    <global offwidth="1280" offheight="720"/>
  </visual>
  <option gravity="0 0 0"/>
  <actuator>
    <position name="if_slider_link_pos" joint="if_slider_link" kp="2.0" ctrlrange="0.0 0.019"/>
    <position name="if_slider_abpart_link_pos" joint="if_slider_abpart_link" kp="2.0" ctrlrange="-3.14159 3.14159"/>
    <position name="if_proximal_link_pos" joint="if_proximal_link" kp="2.0" ctrlrange="-3.14159 3.14159"/>
    <position name="if_distal_link_pos" joint="if_distal_link" kp="2.0" ctrlrange="-3.14159 3.14159"/>
    <position name="if_connecting_link_pos" joint="if_connecting_link" kp="2.0" ctrlrange="-3.14159 3.14159"/>
    <position name="mf_slider_link_pos" joint="mf_slider_link" kp="2.0" ctrlrange="0.0 0.019"/>
    <position name="mf_slider_abpart_link_pos" joint="mf_slider_abpart_link" kp="2.0" ctrlrange="-3.14159 3.14159"/>
    <position name="mf_proximal_link_pos" joint="mf_proximal_link" kp="2.0" ctrlrange="-3.14159 3.14159"/>
    <position name="mf_distal_link_pos" joint="mf_distal_link" kp="2.0" ctrlrange="-3.14159 3.14159"/>
    <position name="mf_connecting_link_pos" joint="mf_connecting_link" kp="2.0" ctrlrange="-3.14159 3.14159"/>
    <position name="rf_slider_link_pos" joint="rf_slider_link" kp="2.0" ctrlrange="0.0 0.019"/>
    <position name="rf_slider_abpart_link_pos" joint="rf_slider_abpart_link" kp="2.0" ctrlrange="-3.14159 3.14159"/>
    <position name="rf_proximal_link_pos" joint="rf_proximal_link" kp="2.0" ctrlrange="-3.14159 3.14159"/>
    <position name="rf_distal_link_pos" joint="rf_distal_link" kp="2.0" ctrlrange="-3.14159 3.14159"/>
    <position name="rf_connecting_link_pos" joint="rf_connecting_link" kp="2.0" ctrlrange="-3.14159 3.14159"/>
    <position name="lf_slider_link_pos" joint="lf_slider_link" kp="2.0" ctrlrange="0.0 0.019"/>
    <position name="lf_slider_abpart_link_pos" joint="lf_slider_abpart_link" kp="2.0" ctrlrange="-3.14159 3.14159"/>
    <position name="lf_proximal_link_pos" joint="lf_proximal_link" kp="2.0" ctrlrange="-3.14159 3.14159"/>
    <position name="lf_distal_link_pos" joint="lf_distal_link" kp="2.0" ctrlrange="-3.14159 3.14159"/>
    <position name="lf_connecting_link_pos" joint="lf_connecting_link" kp="2.0" ctrlrange="-3.14159 3.14159"/>
    <position name="th_root_link_pos" joint="th_root_link" kp="2.0" ctrlrange="0.0 1.57"/>
    <position name="th_proximal_link_pos" joint="th_proximal_link" kp="2.0" ctrlrange="-3.14159 3.14159"/>
    <position name="th_slider_link_pos" joint="th_slider_link" kp="2.0" ctrlrange="0.0 0.01"/>
    <position name="th_connecting_link_pos" joint="th_connecting_link" kp="2.0" ctrlrange="-3.14159 3.14159"/>
    <position name="th_distal_link_pos" joint="th_distal_link" kp="2.0" ctrlrange="-3.14159 3.14159"/>
  </actuator>
</mujoco>
