<?xml version='1.0' encoding='utf-8'?>
<robot name="rohand_left">
  <link name="base_link">
    <inertial>
      <origin xyz="-0.0600175992226992 0.00173674758946424 0.003647460158999" rpy="0 0 0" />
      <mass value="0.0559618850523164" />
      <inertia ixx="2.50232879484508E-05" ixy="1.21179219483759E-06" ixz="1.3120954628882E-06" iyy="3.35110967631875E-05" iyz="4.46372025543979E-07" izz="5.16602242361882E-05" />
    </inertial>
    <visual>
      <origin xyz="0 0 0" rpy="0 0 0" />
      <geometry>
        <mesh filename="base_link.STL" />
      </geometry>
      <material name="">
        <color rgba="1 1 1 1" />
      </material>
    </visual>
    <collision>
      <origin xyz="0 0 0" rpy="0 0 0" />
      <geometry>
        <mesh filename="base_link.STL" />
      </geometry>
    </collision>
  </link>
  <link name="if_slider_link">
    <inertial>
      <origin xyz="-0.013831882124786 0.00115456036788866 1.1863450844439E-06" rpy="0 0 0" />
      <mass value="0.00048911221771827" />
      <inertia ixx="4.60387241005875E-09" ixy="2.8127898863501E-09" ixz="-3.18026655344593E-12" iyy="3.82302567697763E-08" iyz="7.17688117200499E-11" izz="3.92692763677803E-08" />
    </inertial>
    <visual>
      <origin xyz="0 0 0" rpy="0 0 0" />
      <geometry>
        <mesh filename="if_slider_link.STL" />
      </geometry>
      <material name="">
        <color rgba="1 1 1 1" />
      </material>
    </visual>
    <collision>
      <origin xyz="0 0 0" rpy="0 0 0" />
      <geometry>
        <mesh filename="if_slider_link.STL" />
      </geometry>
    </collision>
  </link>
  <joint name="if_slider_link" type="prismatic">
    <origin xyz="-0.074396 0.026655 -0.0059032" rpy="0 0 0" />
    <parent link="base_link" />
    <child link="if_slider_link" />
    <axis xyz="0.99655 -0.083049 0" />
    <limit lower="0" upper="0.019" effort="0" velocity="0" />
  </joint>
  <link name="if_slider_abpart_link">
    <inertial>
      <origin xyz="-0.0107864188255613 -0.00263940611058044 -0.00013913226482987" rpy="0 0 0" />
      <mass value="0.000419595822746572" />
      <inertia ixx="1.75917796784222E-09" ixy="2.74325143413962E-10" ixz="-6.61499697224064E-10" iyy="5.7335166061789E-09" iyz="9.56844870518539E-11" izz="6.20984539277726E-09" />
    </inertial>
    <visual>
      <origin xyz="0 0 0" rpy="0 0 0" />
      <geometry>
        <mesh filename="if_slider_abpart_link.STL" />
      </geometry>
      <material name="">
        <color rgba="1 1 1 1" />
      </material>
    </visual>
    <collision>
      <origin xyz="0 0 0" rpy="0 0 0" />
      <geometry>
        <mesh filename="if_slider_abpart_link.STL" />
      </geometry>
    </collision>
  </link>
  <joint name="if_slider_abpart_link" type="revolute">
    <origin xyz="-0.02861 0.0058839 -0.00030477" rpy="0 0 0" />
    <parent link="if_slider_link" />
    <child link="if_slider_abpart_link" />
    <axis xyz="0.082734 0.99276 -0.087135" />
  <limit lower="-3.14159" upper="3.14159" effort="1" velocity="10" /></joint>
  <link name="if_proximal_link">
    <inertial>
      <origin xyz="-0.0180401934810981 -0.00594318681409531 -0.00214940799795962" rpy="0 0 0" />
      <mass value="0.00154987032874225" />
      <inertia ixx="6.20379278686707E-08" ixy="7.89401144100231E-09" ixz="2.15078751193785E-09" iyy="1.54247144894286E-07" iyz="1.11019132631612E-09" izz="1.69493178080606E-07" />
    </inertial>
    <visual>
      <origin xyz="0 0 0" rpy="0 0 0" />
      <geometry>
        <mesh filename="if_proximal_link.STL" />
      </geometry>
      <material name="">
        <color rgba="1 1 1 1" />
      </material>
    </visual>
    <collision>
      <origin xyz="0 0 0" rpy="0 0 0" />
      <geometry>
        <mesh filename="if_proximal_link.STL" />
      </geometry>
    </collision>
  </link>
  <joint name="if_proximal_link" type="revolute">
    <origin xyz="-0.11211 0.037738 0.0020371" rpy="0 0 0" />
    <parent link="base_link" />
    <child link="if_proximal_link" />
    <axis xyz="0.082428 0.99278 -0.087177" />
  <limit lower="-3.14159" upper="3.14159" effort="1" velocity="10" /></joint>
  <link name="if_distal_link">
    <inertial>
      <origin xyz="-0.0242417824734568 -0.00576634331785811 -0.00601095840966076" rpy="0 0 0" />
      <mass value="0.0042269383122795" />
      <inertia ixx="9.82682026496381E-08" ixy="2.86098057670537E-08" ixz="-1.10777302806872E-07" iyy="5.59160651416525E-07" iyz="7.3813015969809E-09" izz="5.40423175644971E-07" />
    </inertial>
    <visual>
      <origin xyz="0 0 0" rpy="0 0 0" />
      <geometry>
        <mesh filename="if_distal_link.STL" />
      </geometry>
      <material name="">
        <color rgba="1 1 1 1" />
      </material>
    </visual>
    <collision>
      <origin xyz="0 0 0" rpy="0 0 0" />
      <geometry>
        <mesh filename="if_distal_link.STL" />
      </geometry>
    </collision>
  </link>
  <joint name="if_distal_link" type="revolute">
    <origin xyz="-0.035776 0.0028401 -0.0014841" rpy="0 0 0" />
    <parent link="if_proximal_link" />
    <child link="if_distal_link" />
    <axis xyz="0.082428 0.99278 -0.087177" />
  <limit lower="-3.14159" upper="3.14159" effort="1" velocity="10" /></joint>
  <link name="if_connecting_link">
    <inertial>
      <origin xyz="-0.0154529830298678 -0.00300880066164064 -0.00700719055867323" rpy="0 0 0" />
      <mass value="0.000197692348310411" />
      <inertia ixx="4.07223389206408E-09" ixy="1.11280581546581E-09" ixz="-9.07369152604057E-09" iyy="2.70145409777339E-08" iyz="4.0263808141139E-10" izz="2.30774689922599E-08" />
    </inertial>
    <visual>
      <origin xyz="0 0 0" rpy="0 0 0" />
      <geometry>
        <mesh filename="if_connecting_link.STL" />
      </geometry>
      <material name="">
        <color rgba="1 1 1 1" />
      </material>
    </visual>
    <collision>
      <origin xyz="0 0 0" rpy="0 0 0" />
      <geometry>
        <mesh filename="if_connecting_link.STL" />
      </geometry>
    </collision>
  </link>
  <joint name="if_connecting_link" type="revolute">
    <origin xyz="-0.11976 0.03521 0.0067299" rpy="0 0 0" />
    <parent link="base_link" />
    <child link="if_connecting_link" />
    <axis xyz="0.082428 0.99278 -0.087177" />
  <limit lower="-3.14159" upper="3.14159" effort="1" velocity="10" /></joint>
  <link name="mf_slider_link">
    <inertial>
      <origin xyz="-0.013878747077534 0.000185328089726128 8.622740372069E-08" rpy="0 0 0" />
      <mass value="0.000489112305392741" />
      <inertia ixx="4.3759626088488E-09" ixy="4.42668858430006E-10" ixz="-1.30309167879349E-11" iyy="3.84519195282787E-08" iyz="4.98468697390903E-13" izz="3.92755372638914E-08" />
    </inertial>
    <visual>
      <origin xyz="0 0 0" rpy="0 0 0" />
      <geometry>
        <mesh filename="mf_slider_link.STL" />
      </geometry>
      <material name="">
        <color rgba="1 1 1 1" />
      </material>
    </visual>
    <collision>
      <origin xyz="0 0 0" rpy="0 0 0" />
      <geometry>
        <mesh filename="mf_slider_link.STL" />
      </geometry>
    </collision>
  </link>
  <joint name="mf_slider_link" type="prismatic">
    <origin xyz="-0.076974 0.010077 -0.0016353" rpy="0 0 0" />
    <parent link="base_link" />
    <child link="mf_slider_link" />
    <axis xyz="0.99991 -0.013228 0.00010039" />
    <limit lower="0" upper="0.019" effort="0" velocity="0" />
  </joint>
  <link name="mf_slider_abpart_link">
    <inertial>
      <origin xyz="-0.0105596379857566 -0.00336124088471218 -0.000727211243021133" rpy="0 0 0" />
      <mass value="0.000419595848489683" />
      <inertia ixx="1.78090578752483E-09" ixy="5.23866893151899E-11" ixz="-7.88313295390851E-10" iyy="5.74728451250454E-09" iyz="1.04756066269533E-11" izz="6.17435090190752E-09" />
    </inertial>
    <visual>
      <origin xyz="0 0 0" rpy="0 0 0" />
      <geometry>
        <mesh filename="mf_slider_abpart_link.STL" />
      </geometry>
      <material name="">
        <color rgba="1 1 1 1" />
      </material>
    </visual>
    <collision>
      <origin xyz="0 0 0" rpy="0 0 0" />
      <geometry>
        <mesh filename="mf_slider_abpart_link.STL" />
      </geometry>
    </collision>
  </link>
  <joint name="mf_slider_abpart_link" type="revolute">
    <origin xyz="-0.028951 0.0038841 0" rpy="0 0 0" />
    <parent link="mf_slider_link" />
    <child link="mf_slider_abpart_link" />
    <axis xyz="0.013228 0.99991 -7.2594E-05" />
  <limit lower="-3.14159" upper="3.14159" effort="1" velocity="10" /></joint>
  <link name="mf_proximal_link">
    <inertial>
      <origin xyz="-0.0199797334891479 -0.00693582390555644 -0.00446806914321724" rpy="0 0 0" />
      <mass value="0.00189508780970619" />
      <inertia ixx="7.7805923733235E-08" ixy="2.0676177672704E-09" ixz="-1.00300119994739E-08" iyy="2.3404709814833E-07" iyz="1.32133235333923E-10" izz="2.46206545141109E-07" />
    </inertial>
    <visual>
      <origin xyz="0 0 0" rpy="0 0 0" />
      <geometry>
        <mesh filename="mf_proximal_link.STL" />
      </geometry>
      <material name="">
        <color rgba="1 1 1 1" />
      </material>
    </visual>
    <collision>
      <origin xyz="0 0 0" rpy="0 0 0" />
      <geometry>
        <mesh filename="mf_proximal_link.STL" />
      </geometry>
    </collision>
  </link>
  <joint name="mf_proximal_link" type="revolute">
    <origin xyz="-0.11587 0.017792 0.0069665" rpy="0 0 0" />
    <parent link="base_link" />
    <child link="mf_proximal_link" />
    <axis xyz="0.013244 0.99991 4.2699E-05" />
  <limit lower="-3.14159" upper="3.14159" effort="1" velocity="10" /></joint>
  <link name="mf_distal_link">
    <inertial>
      <origin xyz="-0.0237385164850207 -0.00688494079178079 -0.00679220850075163" rpy="0 0 0" />
      <mass value="0.0042269628029676" />
      <inertia ixx="9.80058679932351E-08" ixy="6.06231538286094E-09" ixz="-1.13827652906676E-07" iyy="5.60810951030143E-07" iyz="1.48885023943624E-09" izz="5.39048309363154E-07" />
    </inertial>
    <visual>
      <origin xyz="0 0 0" rpy="0 0 0" />
      <geometry>
        <mesh filename="mf_distal_link.STL" />
      </geometry>
      <material name="">
        <color rgba="1 1 1 1" />
      </material>
    </visual>
    <collision>
      <origin xyz="0 0 0" rpy="0 0 0" />
      <geometry>
        <mesh filename="mf_distal_link.STL" />
      </geometry>
    </collision>
  </link>
  <joint name="mf_distal_link" type="revolute">
    <origin xyz="-0.040851 0.00054126 -0.0035367" rpy="0 0 0" />
    <parent link="mf_proximal_link" />
    <child link="mf_distal_link" />
    <axis xyz="0.013244 0.99991 2.1055E-05" />
  <limit lower="-3.14159" upper="3.14159" effort="1" velocity="10" /></joint>
  <link name="mf_connecting_link">
    <inertial>
      <origin xyz="-0.0173259476733337 -0.00342060961323612 -0.00839513952079128" rpy="0 0 0" />
      <mass value="0.000216184518525667" />
      <inertia ixx="5.71913358376963E-09" ixy="4.34632649617872E-10" ixz="-1.31282895880665E-08" iyy="3.85063451062604E-08" iyz="1.74009446649164E-10" izz="3.28217930253539E-08" />
    </inertial>
    <visual>
      <origin xyz="0 0 0" rpy="0 0 0" />
      <geometry>
        <mesh filename="mf_connecting_link.STL" />
      </geometry>
      <material name="">
        <color rgba="1 1 1 1" />
      </material>
    </visual>
    <collision>
      <origin xyz="0 0 0" rpy="0 0 0" />
      <geometry>
        <mesh filename="mf_connecting_link.STL" />
      </geometry>
    </collision>
  </link>
  <joint name="mf_connecting_link" type="revolute">
    <origin xyz="-0.12334 0.014341 0.011366" rpy="0 0 0" />
    <parent link="base_link" />
    <child link="mf_connecting_link" />
    <axis xyz="0.013244 0.99991 2.1054E-05" />
  <limit lower="-3.14159" upper="3.14159" effort="1" velocity="10" /></joint>
  <link name="rf_slider_link">
    <inertial>
      <origin xyz="-0.0138578672671499 -0.00078324248832945 1.59405782883433E-07" rpy="0 0 0" />
      <mass value="0.000489112303078988" />
      <inertia ixx="4.48016318899327E-09" ixy="-1.93283010934183E-09" ixz="-1.28464378602607E-11" iyy="3.834771866864E-08" iyz="-3.94300598627811E-13" izz="3.92755371230416E-08" />
    </inertial>
    <visual>
      <origin xyz="0 0 0" rpy="0 0 0" />
      <geometry>
        <mesh filename="rf_slider_link.STL" />
      </geometry>
      <material name="">
        <color rgba="1 1 1 1" />
      </material>
    </visual>
    <collision>
      <origin xyz="0 0 0" rpy="0 0 0" />
      <geometry>
        <mesh filename="rf_slider_link.STL" />
      </geometry>
    </collision>
  </link>
  <joint name="rf_slider_link" type="prismatic">
    <origin xyz="-0.074498 -0.0072492 -0.0023801" rpy="0 0 0" />
    <parent link="base_link" />
    <child link="rf_slider_link" />
    <axis xyz="0.9984 0.056554 9.5082E-05" />
    <limit lower="0" upper="0.019" effort="0" velocity="0" />
  </joint>
  <link name="rf_slider_abpart_link">
    <inertial>
      <origin xyz="-0.0103066808663681 -0.00409004748705058 -0.000613628353270297" rpy="0 0 0" />
      <mass value="0.000419595841745906" />
      <inertia ixx="1.77645736028942E-09" ixy="-2.25058409313133E-10" ixz="-7.39578165961404E-10" iyy="5.73522260886412E-09" iyz="-4.18409260159825E-11" izz="6.19086108929486E-09" />
    </inertial>
    <visual>
      <origin xyz="0 0 0" rpy="0 0 0" />
      <geometry>
        <mesh filename="rf_slider_abpart_link.STL" />
      </geometry>
      <material name="">
        <color rgba="1 1 1 1" />
      </material>
    </visual>
    <collision>
      <origin xyz="0 0 0" rpy="0 0 0" />
      <geometry>
        <mesh filename="rf_slider_abpart_link.STL" />
      </geometry>
    </collision>
  </link>
  <joint name="rf_slider_abpart_link" type="revolute">
    <origin xyz="-0.029152 0.0018551 0" rpy="0 0 0" />
    <parent link="rf_slider_link" />
    <child link="rf_slider_abpart_link" />
    <axis xyz="-0.056554 0.9984 -7.942E-05" />
  <limit lower="-3.14159" upper="3.14159" effort="1" velocity="10" /></joint>
  <link name="rf_proximal_link">
    <inertial>
      <origin xyz="-0.0169549089835899 -0.00817221852533054 -0.00333737800773532" rpy="0 0 0" />
      <mass value="0.00154985371268108" />
      <inertia ixx="6.16430441306532E-08" ixy="-5.27625854931828E-09" ixz="-1.35085566211527E-09" iyy="1.54505752798055E-07" iyz="-7.80848576926748E-11" izz="1.69627005510225E-07" />
    </inertial>
    <visual>
      <origin xyz="0 0 0" rpy="0 0 0" />
      <geometry>
        <mesh filename="rf_proximal_link.STL" />
      </geometry>
      <material name="">
        <color rgba="1 1 1 1" />
      </material>
    </visual>
    <collision>
      <origin xyz="0 0 0" rpy="0 0 0" />
      <geometry>
        <mesh filename="rf_proximal_link.STL" />
      </geometry>
    </collision>
  </link>
  <joint name="rf_proximal_link" type="revolute">
    <origin xyz="-0.11364 -0.0022565 0.0062163" rpy="0 0 0" />
    <parent link="base_link" />
    <child link="rf_proximal_link" />
    <axis xyz="-0.05658 0.9984 2.102E-05" />
  <limit lower="-3.14159" upper="3.14159" effort="1" velocity="10" /></joint>
  <link name="rf_distal_link">
    <inertial>
      <origin xyz="-0.022696111452442 -0.00849649226724736 -0.00835478756750876" rpy="0 0 0" />
      <mass value="0.00422730983553646" />
      <inertia ixx="1.16496262714894E-07" ixy="-2.5261364839183E-08" ixz="-1.41993969994743E-07" iyy="5.59567957009536E-07" iyz="-8.07053877471632E-09" izz="5.22034079641838E-07" />
    </inertial>
    <visual>
      <origin xyz="0 0 0" rpy="0 0 0" />
      <geometry>
        <mesh filename="rf_distal_link.STL" />
      </geometry>
      <material name="">
        <color rgba="1 1 1 1" />
      </material>
    </visual>
    <collision>
      <origin xyz="0 0 0" rpy="0 0 0" />
      <geometry>
        <mesh filename="rf_distal_link.STL" />
      </geometry>
    </collision>
  </link>
  <joint name="rf_distal_link" type="revolute">
    <origin xyz="-0.035766 -0.0020268 -0.0026198" rpy="0 0 0" />
    <parent link="rf_proximal_link" />
    <child link="rf_distal_link" />
    <axis xyz="-0.05658 0.9984 2.102E-05" />
  <limit lower="-3.14159" upper="3.14159" effort="1" velocity="10" /></joint>
  <link name="rf_connecting_link">
    <inertial>
      <origin xyz="-0.0182151281756033 0.0164706758619828 -0.00574282817068492" rpy="0 0 0" />
      <mass value="0.000197692354337264" />
      <inertia ixx="4.92838052690555E-09" ixy="-1.25465921189233E-09" ixz="-9.87171474508207E-09" iyy="2.70004879799029E-08" iyz="-5.59333811535522E-10" izz="2.22353755729308E-08" />
    </inertial>
    <visual>
      <origin xyz="0 0 0" rpy="0 0 0" />
      <geometry>
        <mesh filename="rf_connecting_link.STL" />
      </geometry>
      <material name="">
        <color rgba="1 1 1 1" />
      </material>
    </visual>
    <collision>
      <origin xyz="0 0 0" rpy="0 0 0" />
      <geometry>
        <mesh filename="rf_connecting_link.STL" />
      </geometry>
    </collision>
  </link>
  <joint name="rf_connecting_link" type="revolute">
    <origin xyz="-0.11723 -0.027174 0.008365" rpy="0 0 0" />
    <parent link="base_link" />
    <child link="rf_connecting_link" />
    <axis xyz="-0.05658 0.9984 2.102E-05" />
  <limit lower="-3.14159" upper="3.14159" effort="1" velocity="10" /></joint>
  <link name="lf_slider_link">
    <inertial>
      <origin xyz="-0.0144167564876969 -0.00171205925869156 3.81352530457336E-07" rpy="0 0 0" />
      <mass value="0.000510662528391611" />
      <inertia ixx="4.9365491500063E-09" ixy="-3.99382130462206E-09" ixz="-3.82896929119076E-12" iyy="3.79994364556094E-08" iyz="-7.87026435487919E-11" izz="3.93595008041777E-08" />
    </inertial>
    <visual>
      <origin xyz="0 0 0" rpy="0 0 0" />
      <geometry>
        <mesh filename="lf_slider_link.STL" />
      </geometry>
      <material name="">
        <color rgba="1 1 1 1" />
      </material>
    </visual>
    <collision>
      <origin xyz="0 0 0" rpy="0 0 0" />
      <geometry>
        <mesh filename="lf_slider_link.STL" />
      </geometry>
    </collision>
  </link>
  <joint name="lf_slider_link" type="prismatic">
    <origin xyz="-0.070847 -0.024182 -0.0048997" rpy="0 0 0" />
    <parent link="base_link" />
    <child link="lf_slider_link" />
    <axis xyz="0.99301 0.11803 8.2704E-05" />
    <limit lower="0" upper="0.019" effort="0" velocity="0" />
  </joint>
  <link name="lf_slider_abpart_link">
    <inertial>
      <origin xyz="-0.0100358483607181 -0.00463982379624511 -0.00104236140669513" rpy="0 0 0" />
      <mass value="0.000419595826532552" />
      <inertia ixx="1.82121196852816E-09" ixy="-3.9802967870408E-10" ixz="-7.80769700533061E-10" iyy="5.71210051864852E-09" iyz="-1.29906442115816E-10" izz="6.16922773505282E-09" />
    </inertial>
    <visual>
      <origin xyz="0 0 0" rpy="0 0 0" />
      <geometry>
        <mesh filename="lf_slider_abpart_link.STL" />
      </geometry>
      <material name="">
        <color rgba="1 1 1 1" />
      </material>
    </visual>
    <collision>
      <origin xyz="0 0 0" rpy="0 0 0" />
      <geometry>
        <mesh filename="lf_slider_abpart_link.STL" />
      </geometry>
    </collision>
  </link>
  <joint name="lf_slider_abpart_link" type="revolute">
    <origin xyz="-0.029209 4.0116E-05 0.00030326" rpy="0 0 0" />
    <parent link="lf_slider_link" />
    <child link="lf_slider_abpart_link" />
    <axis xyz="-0.11759 0.98923 0.08715" />
  <limit lower="-3.14159" upper="3.14159" effort="1" velocity="10" /></joint>
  <link name="lf_proximal_link">
    <inertial>
      <origin xyz="-0.0146179038371213 -0.00865933449081624 -0.00404765240562847" rpy="0 0 0" />
      <mass value="0.00136661208486985" />
      <inertia ixx="5.65517835433433E-08" ixy="-6.43465965682621E-09" ixz="-2.86652645878912E-09" iyy="1.12186752570062E-07" iyz="-1.61029658148309E-09" izz="1.27246247373284E-07" />
    </inertial>
    <visual>
      <origin xyz="0 0 0" rpy="0 0 0" />
      <geometry>
        <mesh filename="lf_proximal_link.STL" />
      </geometry>
      <material name="">
        <color rgba="1 1 1 1" />
      </material>
    </visual>
    <collision>
      <origin xyz="0 0 0" rpy="0 0 0" />
      <geometry>
        <mesh filename="lf_proximal_link.STL" />
      </geometry>
    </collision>
  </link>
  <joint name="lf_proximal_link" type="revolute">
    <origin xyz="-0.11032 -0.022406 0.0042916" rpy="0 0 0" />
    <parent link="base_link" />
    <child link="lf_proximal_link" />
    <axis xyz="-0.11759 0.98923 0.087106" />
  <limit lower="-3.14159" upper="3.14159" effort="1" velocity="10" /></joint>
  <link name="lf_distal_link">
    <inertial>
      <origin xyz="-0.014370796499536 -0.008390245956126 -0.00657795990320131" rpy="0 0 0" />
      <mass value="0.00262042947413116" />
      <inertia ixx="5.14865241597797E-08" ixy="-8.72354900376063E-09" ixz="-3.78475585620367E-08" iyy="1.52166371803539E-07" iyz="-3.91942047531457E-09" izz="1.45327848752015E-07" />
    </inertial>
    <visual>
      <origin xyz="0 0 0" rpy="0 0 0" />
      <geometry>
        <mesh filename="lf_distal_link.STL" />
      </geometry>
      <material name="">
        <color rgba="1 1 1 1" />
      </material>
    </visual>
    <collision>
      <origin xyz="0 0 0" rpy="0 0 0" />
      <geometry>
        <mesh filename="lf_distal_link.STL" />
      </geometry>
    </collision>
  </link>
  <joint name="lf_distal_link" type="revolute">
    <origin xyz="-0.031562 -0.0034532 -0.003392" rpy="0 0 0" />
    <parent link="lf_proximal_link" />
    <child link="lf_distal_link" />
    <axis xyz="-0.11759 0.98923 0.087106" />
  <limit lower="-3.14159" upper="3.14159" effort="1" velocity="10" /></joint>
  <link name="lf_connecting_link">
    <inertial>
      <origin xyz="-0.0121624488477445 -0.00439577388851597 -0.00839995412997622" rpy="0 0 0" />
      <mass value="0.000176980932045691" />
      <inertia ixx="4.93706927346499E-09" ixy="-1.08018597686527E-09" ixz="-8.19110691260071E-09" iyy="2.00115768299624E-08" iyz="-5.47674876971474E-10" izz="1.52537402638674E-08" />
    </inertial>
    <visual>
      <origin xyz="0 0 0" rpy="0 0 0" />
      <geometry>
        <mesh filename="lf_connecting_link.STL" />
      </geometry>
      <material name="">
        <color rgba="1 1 1 1" />
      </material>
    </visual>
    <collision>
      <origin xyz="0 0 0" rpy="0 0 0" />
      <geometry>
        <mesh filename="lf_connecting_link.STL" />
      </geometry>
    </collision>
  </link>
  <joint name="lf_connecting_link" type="revolute">
    <origin xyz="-0.11723 -0.027174 0.008365" rpy="0 0 0" />
    <parent link="base_link" />
    <child link="lf_connecting_link" />
    <axis xyz="-0.11759 0.98924 0.087085" />
  <limit lower="-3.14159" upper="3.14159" effort="1" velocity="10" /></joint>
  <link name="th_root_link">
    <inertial>
      <origin xyz="-0.0182055985206398 0.00620277969837987 -0.00602504691008154" rpy="0 0 0" />
      <mass value="0.00217782401907458" />
      <inertia ixx="1.92048266024776E-07" ixy="8.02008085705929E-08" ixz="-1.58292817167637E-08" iyy="1.97385210109919E-07" iyz="2.8437183719772E-08" izz="2.25369870005598E-07" />
    </inertial>
    <visual>
      <origin xyz="0 0 0" rpy="0 0 0" />
      <geometry>
        <mesh filename="th_root_link.STL" />
      </geometry>
      <material name="">
        <color rgba="1 1 1 1" />
      </material>
    </visual>
    <collision>
      <origin xyz="0 0 0" rpy="0 0 0" />
      <geometry>
        <mesh filename="th_root_link.STL" />
      </geometry>
    </collision>
  </link>
  <joint name="th_root_link" type="revolute">
    <origin xyz="-0.024656 0.019554 -0.018266" rpy="0 0 0" />
    <parent link="base_link" />
    <child link="th_root_link" />
    <axis xyz="-0.97616 0.01293 -0.21667" />
    <limit lower="0" upper="1.57" effort="0" velocity="0" />
  </joint>
  <link name="th_proximal_link">
    <inertial>
      <origin xyz="-0.00770018684827107 0.011788302524247 -0.0170644760229541" rpy="0 0 0" />
      <mass value="0.00501318922026079" />
      <inertia ixx="2.07793414915373E-06" ixy="-3.98829361861836E-12" ixz="3.13964194356435E-13" iyy="1.50672511173197E-06" iyz="6.80394768150803E-07" izz="6.75564984341832E-07" />
    </inertial>
    <visual>
      <origin xyz="0 0 0" rpy="0 0 0" />
      <geometry>
        <mesh filename="th_proximal_link.STL" />
      </geometry>
      <material name="">
        <color rgba="1 1 1 1" />
      </material>
    </visual>
    <collision>
      <origin xyz="0 0 0" rpy="0 0 0" />
      <geometry>
        <mesh filename="th_proximal_link.STL" />
      </geometry>
    </collision>
  </link>
  <joint name="th_proximal_link" type="revolute">
    <origin xyz="-0.025097 0.021667 -0.015581" rpy="0.14303 1.3497 0.14655" />
    <parent link="th_root_link" />
    <child link="th_proximal_link" />
    <axis xyz="1 0 0" />
  <limit lower="-3.14159" upper="3.14159" effort="1" velocity="10" /></joint>
  <link name="th_slider_link">
    <inertial>
      <origin xyz="-0.0119352170255541 0.00825053452681332 -0.00238381819650774" rpy="0 0 0" />
      <mass value="0.000966918573679238" />
      <inertia ixx="4.78147534251827E-08" ixy="2.60369555753437E-08" ixz="-1.95859134260407E-09" iyy="5.57308268866282E-08" iyz="5.63509107044141E-09" izz="6.02170914313473E-08" />
    </inertial>
    <visual>
      <origin xyz="0 0 0" rpy="0 0 0" />
      <geometry>
        <mesh filename="th_slider_link.STL" />
      </geometry>
      <material name="">
        <color rgba="1 1 1 1" />
      </material>
    </visual>
    <collision>
      <origin xyz="0 0 0" rpy="0 0 0" />
      <geometry>
        <mesh filename="th_slider_link.STL" />
      </geometry>
    </collision>
  </link>
  <joint name="th_slider_link" type="prismatic">
    <origin xyz="-0.0077 0.0027693 -0.00023667" rpy="0 -1.352 -0.032034" />
    <parent link="th_proximal_link" />
    <child link="th_slider_link" />
    <axis xyz="-0.76198 0.63028 -0.14877" />
    <limit lower="0" upper="0.01" effort="0" velocity="0" />
  </joint>
  <link name="th_connecting_link">
    <inertial>
      <origin xyz="-0.00506957828509727 0.0022529909165182 0.00365191633381741" rpy="0 0 0" />
      <mass value="0.000334843777726033" />
      <inertia ixx="2.97269012068611E-09" ixy="1.34809608463028E-09" ixz="-4.23656553440134E-10" iyy="5.01992883871934E-09" iyz="2.98232658947671E-10" izz="4.99074064887975E-09" />
    </inertial>
    <visual>
      <origin xyz="0 0 0" rpy="0 0 0" />
      <geometry>
        <mesh filename="th_connecting_link.STL" />
      </geometry>
      <material name="">
        <color rgba="1 1 1 1" />
      </material>
    </visual>
    <collision>
      <origin xyz="0 0 0" rpy="0 0 0" />
      <geometry>
        <mesh filename="th_connecting_link.STL" />
      </geometry>
    </collision>
  </link>
  <joint name="th_connecting_link" type="revolute">
    <origin xyz="-0.027697 0.024088 -0.010084" rpy="0 0 0" />
    <parent link="th_slider_link" />
    <child link="th_connecting_link" />
    <axis xyz="0.21699 0.032029 -0.97565" />
  <limit lower="-3.14159" upper="3.14159" effort="1" velocity="10" /></joint>
  <link name="th_distal_link">
    <inertial>
      <origin xyz="-0.00470321656966432 0.0108131649563331 0.00709251414154711" rpy="0 0 0" />
      <mass value="0.00509494222453049" />
      <inertia ixx="2.72112772656721E-07" ixy="5.86600483065481E-08" ixz="8.76444627770057E-09" iyy="2.01886474111303E-07" iyz="1.17477856405696E-08" izz="2.43694502794788E-07" />
    </inertial>
    <visual>
      <origin xyz="0 0 0" rpy="0 0 0" />
      <geometry>
        <mesh filename="th_distal_link.STL" />
      </geometry>
      <material name="">
        <color rgba="1 1 1 1" />
      </material>
    </visual>
    <collision>
      <origin xyz="0 0 0" rpy="0 0 0" />
      <geometry>
        <mesh filename="th_distal_link.STL" />
      </geometry>
    </collision>
  </link>
  <joint name="th_distal_link" type="revolute">
    <origin xyz="-0.00010351 0.023735 -0.046849" rpy="0 -1.352 -0.032034" />
    <parent link="th_proximal_link" />
    <child link="th_distal_link" />
    <axis xyz="0.21698 0.032029 -0.97565" />
  <limit lower="-3.14159" upper="3.14159" effort="1" velocity="10" /></joint>
</robot>