<mujoco model="svh">
  <compiler angle="radian" meshdir="./" autolimits="true"/>

  <option gravity="0 0 0" integrator="implicitfast" timestep="0.002" solver="Newton" iterations="200" tolerance="1e-12" impratio="100"/>

  <default>
    <joint armature="0.01" damping="0.1"/>
    <position kp="1200" dampratio="1"/>
    <geom density="0"/>
  </default>

  <visual>
    <global offwidth="1280" offheight="1280"/>
  </visual>

  <asset>
    <texture type="skybox" builtin="gradient" rgb1="0.3 0.5 0.7" rgb2="0 0 0" width="512" height="3072"/>
    <texture type="2d" name="groundplane" builtin="checker" mark="edge" rgb1="0.2 0.3 0.4" rgb2="0.1 0.2 0.3" markrgb="0.8 0.8 0.8" width="300" height="300"/>
    <material name="groundplane" texture="groundplane" texrepeat="5 5" reflectance="0.2"/>
    <mesh name="base10" content_type="model/obj" file="meshes/visual/base10.obj"/>
    <mesh name="h10" content_type="model/obj" file="meshes/visual/h10.obj"/>
    <mesh name="h11" content_type="model/obj" file="meshes/visual/h11.obj"/>
    <mesh name="d10" content_type="model/obj" file="meshes/visual/d10.obj"/>
    <mesh name="d11" content_type="model/obj" file="meshes/visual/d11.obj"/>
    <mesh name="d12" content_type="model/obj" file="meshes/visual/d12.obj"/>
    <mesh name="d13" content_type="model/obj" file="meshes/visual/d13.obj"/>
    <mesh name="f10_f20" content_type="model/obj" file="meshes/visual/f10_f20.obj"/>
    <mesh name="f11" content_type="model/obj" file="meshes/visual/f11.obj"/>
    <mesh name="f12" content_type="model/obj" file="meshes/visual/f12.obj"/>
    <mesh name="finger_tip" content_type="model/obj" file="meshes/visual/finger_tip.obj"/>
    <mesh name="f21" content_type="model/obj" file="meshes/visual/f21.obj"/>
    <mesh name="f22_f32" content_type="model/obj" file="meshes/visual/f22_f32.obj"/>
    <mesh name="f30_f40" content_type="model/obj" file="meshes/visual/f30_f40.obj"/>
    <mesh name="f31" content_type="model/obj" file="meshes/visual/f31.obj"/>
    <mesh name="f41" content_type="model/obj" file="meshes/visual/f41.obj"/>
    <mesh name="f42" content_type="model/obj" file="meshes/visual/f42.obj"/>
  </asset>

  <worldbody>
    <light pos="0 0 1.5" dir="0 0 -1" directional="true"/>
    <geom name="floor" size="0 0 0.05" type="plane" material="groundplane"/>
    <geom pos="0 0 -0.032" quat="0.707109 0 0 -0.707105" type="mesh" contype="0" conaffinity="0" group="1" mesh="base10"/>
    <geom size="0.045 0.0225" pos="0 0 -0.009" quat="0.707109 0 0 -0.707105" type="cylinder"/>
    <geom quat="0.707109 0 0 -0.707105" type="mesh" contype="0" conaffinity="0" group="1" mesh="h10"/>
    <geom size="0.025 0.025 0.013" pos="0 0 0.013" quat="0.707109 0 0 -0.707105" type="box"/>
    <geom size="0.0292 0.019 0.03205" pos="-0.00963004 0.00572994 0.05747" quat="0.707109 0 0 -0.707105" type="box"/>
    <geom size="0.021 0.019 0.0075" pos="-0.00963006 0.00999994 0.096" quat="0.707109 0 0 -0.707105" type="box"/>
    <geom pos="-0.02634 1.10583e-06 0.110001" quat="0.707141 -3.18183e-05 -0.707073 -3.18213e-05" type="mesh" contype="0" conaffinity="0" group="1" mesh="f10_f20"/>
    <geom size="0.01" pos="-0.01634 2.05829e-07 0.11" quat="0.707141 -3.18183e-05 -0.707073 -3.18213e-05"/>
    <body name="right_hand_z" pos="0.0131299 0.0169001 0" quat="0.991445 -1.37053e-05 0.130526 0.000104102">
      <inertial pos="0 0 0" mass="0.001" diaginertia="1e-9 1e-9 1e-9"/>
      <joint name="right_hand_Thumb_Opposition" pos="0 0 0" axis="0 0 -1" range="0 0.9879"/>
      <geom pos="0 0 0.02442" quat="1 0 0 0" type="mesh" contype="0" conaffinity="0" group="1" mesh="d10"/>
      <geom size="0.012 0.0094 0.004" pos="0 0 0.02842" type="box"/>
      <geom size="0.003 0.012 0.0165" pos="0.0125 0 0.04292" type="box"/>
      <geom size="0.003 0.012 0.0165" pos="-0.0125 0 0.04292" type="box"/>
      <body name="right_hand_a" pos="0 0 0.04596" quat="0.329787 0.625494 0.329779 0.625494">
        <inertial pos="0 0 0" mass="0.001" diaginertia="1e-9 1e-9 1e-9"/>
        <joint name="right_hand_Thumb_Flexion" pos="0 0 0" axis="0 0 1" range="0 0.9704"/>
        <geom type="mesh" contype="0" conaffinity="0" group="1" mesh="d11"/>
        <geom type="mesh" mesh="d11"/>
        <body name="right_hand_b" pos="0.0485 0 0">
          <inertial pos="0 0 0" mass="0.001" diaginertia="1e-9 1e-9 1e-9"/>
          <joint name="right_hand_j3" pos="0 0 0" axis="0 0 1" range="0 0.98506"/>
          <geom type="mesh" contype="0" conaffinity="0" group="1" mesh="d12"/>
          <geom type="mesh" mesh="d12"/>
          <body name="right_hand_c" pos="0.03 0 0">
            <inertial pos="0 0 0" mass="0.001" diaginertia="1e-9 1e-9 1e-9"/>
            <joint name="right_hand_j4" pos="0 0 0" axis="0 0 1" range="0 1.406"/>
            <geom type="mesh" contype="0" conaffinity="0" group="1" mesh="d13"/>
            <geom type="mesh" mesh="d13"/>
          </body>
        </body>
      </body>
    </body>
    <body name="right_hand_e2" pos="-0.00712988 -0.0184 0.0375" quat="0.707109 0 0 -0.707105">
      <inertial pos="0 0 0" mass="0.001" diaginertia="1e-9 1e-9 1e-9"/>
      <joint name="right_hand_j5" pos="0 0 0" axis="0 0 1" range="0 0.98786"/>
      <geom pos="-0.0007 0 -0.01002" quat="1 0 0 0" type="mesh" contype="0" conaffinity="0" group="1" mesh="h11"/>
      <geom size="0.0123 0.0175 0.0282" pos="0.016 0 0.02" type="box"/>
      <geom size="0.006 0.009 0.0105" pos="0.0032 -0.0083 0.048" type="box"/>
      <body name="right_hand_virtual_j" pos="0.003855 -0.006 0.0655" quat="0.500048 -0.5 -0.5 -0.499952">
        <inertial pos="0 0 0" mass="0.001" diaginertia="1e-9 1e-9 1e-9"/>
        <joint name="right_hand_ring_spread" pos="0 0 0" axis="0 0 1" range="0 0.28833"/>
        <geom pos="0 0 -0.01321" quat="1 0 0 0" type="mesh" contype="0" conaffinity="0" group="1" mesh="f30_f40"/>
        <geom size="0.01" pos="0 0 -0.00321"/>
        <body name="right_hand_j" quat="0.707141 0.707073 0 0">
          <inertial pos="0 0 0" mass="0.001" diaginertia="1e-9 1e-9 1e-9"/>
          <joint name="right_hand_Ring_Finger" pos="0 0 0" axis="0 0 1" range="0 0.98175"/>
          <geom type="mesh" contype="0" conaffinity="0" group="1" mesh="f31"/>
          <geom type="mesh" mesh="f31"/>
          <body name="right_hand_n" pos="0.05004 0 0">
            <inertial pos="0 0 0" mass="0.001" diaginertia="1e-9 1e-9 1e-9"/>
            <joint name="right_hand_j12" pos="0 0 0" axis="0 0 1" range="0 1.334"/>
            <geom type="mesh" contype="0" conaffinity="0" group="1" mesh="f22_f32"/>
            <geom type="mesh" mesh="f22_f32"/>
            <body name="right_hand_r" pos="0.032 0 0">
              <inertial pos="0 0 0" mass="0.001" diaginertia="1e-9 1e-9 1e-9"/>
              <joint name="right_hand_j16" pos="0 0 0" axis="0 0 1" range="0 1.395"/>
              <geom type="mesh" contype="0" conaffinity="0" group="1" mesh="finger_tip"/>
              <geom type="mesh" mesh="finger_tip"/>
            </body>
          </body>
        </body>
      </body>
      <body name="right_hand_virtual_i" pos="0.025355 -0.006 0.056" quat="0.500048 -0.5 -0.5 -0.499952">
        <inertial pos="0 0 0" mass="0.001" diaginertia="1e-9 1e-9 1e-9"/>
        <joint name="right_hand_Finger_Spread" pos="0 0 0" axis="0 0 1" range="0 0.5829"/>
        <geom pos="0 0 -0.01321" quat="1 0 0 0" type="mesh" contype="0" conaffinity="0" group="1" mesh="f30_f40"/>
        <geom size="0.01" pos="0 0 -0.00321"/>
        <body name="right_hand_i" quat="0.707141 0.707073 0 0">
          <inertial pos="0 0 0" mass="0.001" diaginertia="1e-9 1e-9 1e-9"/>
          <joint name="right_hand_Pinky" pos="0 0 0" axis="0 0 1" range="0 0.98175"/>
          <geom type="mesh" contype="0" conaffinity="0" group="1" mesh="f41"/>
          <geom type="mesh" mesh="f41"/>
          <body name="right_hand_m" pos="0.04454 0 0">
            <inertial pos="0 0 0" mass="0.001" diaginertia="1e-9 1e-9 1e-9"/>
            <joint name="right_hand_j13" pos="0 0 0" axis="0 0 1" range="0 1.334"/>
            <geom type="mesh" contype="0" conaffinity="0" group="1" mesh="f42"/>
            <geom type="mesh" mesh="f42"/>
            <body name="right_hand_q" pos="0.022 0 0">
              <inertial pos="0 0 0" mass="0.001" diaginertia="1e-9 1e-9 1e-9"/>
              <joint name="right_hand_j17" pos="0 0 0" axis="0 0 1" range="0 1.3971"/>
              <geom type="mesh" contype="0" conaffinity="0" group="1" mesh="finger_tip"/>
              <geom type="mesh" mesh="finger_tip"/>
            </body>
          </body>
        </body>
      </body>
    </body>
    <body name="right_hand_virtual_l" pos="-0.0131302 0.0249999 0.11" quat="0.707141 -3.18183e-05 -0.707073 -3.18213e-05">
      <inertial pos="0 0 0" mass="0.001" diaginertia="1e-9 1e-9 1e-9"/>
      <joint name="right_hand_index_spread" pos="0 0 0" axis="0 0 1" range="0 0.28833"/>
      <geom pos="0 0 0.01321" quat="1 0 0 0" type="mesh" contype="0" conaffinity="0" group="1" mesh="f10_f20"/>
      <geom size="0.01" pos="0 0 0.00121"/>
      <body name="right_hand_l" quat="0.707141 -0.707073 0 0">
        <inertial pos="0 0 0" mass="0.001" diaginertia="1e-9 1e-9 1e-9"/>
        <joint name="right_hand_Index_Finger_Proximal" pos="0 0 0" axis="0 0 1" range="0 0.79849"/>
        <geom type="mesh" contype="0" conaffinity="0" group="1" mesh="f11"/>
        <geom type="mesh" mesh="f11"/>
        <body name="right_hand_p" pos="0.04804 0 0">
          <inertial pos="0 0 0" mass="0.001" diaginertia="1e-9 1e-9 1e-9"/>
          <joint name="right_hand_Index_Finger_Distal" pos="0 0 0" axis="0 0 1" range="0 1.334"/>
          <geom type="mesh" contype="0" conaffinity="0" group="1" mesh="f12"/>
          <geom type="mesh" mesh="f12"/>
          <body name="right_hand_t" pos="0.026 0 0">
            <inertial pos="0 0 0" mass="0.001" diaginertia="1e-9 1e-9 1e-9"/>
            <joint name="right_hand_j14" pos="0 0 0" axis="0 0 1" range="0 1.394"/>
            <geom type="mesh" contype="0" conaffinity="0" group="1" mesh="finger_tip"/>
            <geom type="mesh" mesh="finger_tip"/>
          </body>
        </body>
      </body>
    </body>
    <body name="right_hand_k" pos="-0.01313 -8.30708e-08 0.11" quat="0.500026 -0.500022 -0.499977 -0.499974">
      <inertial pos="0 0 0" mass="0.001" diaginertia="1e-9 1e-9 1e-9"/>
      <joint name="right_hand_Middle_Finger_Proximal" pos="0 0 0" axis="0 0 1" range="0 0.79849"/>
      <geom type="mesh" contype="0" conaffinity="0" group="1" mesh="f21"/>
      <geom type="mesh" mesh="f21"/>
      <body name="right_hand_o" pos="0.05004 0 0">
        <inertial pos="0 0 0" mass="0.001" diaginertia="1e-9 1e-9 1e-9"/>
        <joint name="right_hand_Middle_Finger_Distal" pos="0 0 0" axis="0 0 1" range="0 1.334"/>
        <geom type="mesh" contype="0" conaffinity="0" group="1" mesh="f22_f32"/>
        <geom type="mesh" mesh="f22_f32"/>
        <body name="right_hand_s" pos="0.032 0 0">
          <inertial pos="0 0 0" mass="0.001" diaginertia="1e-9 1e-9 1e-9"/>
          <joint name="right_hand_j15" pos="0 0 0" axis="0 0 1" range="0 1.334"/>
          <geom type="mesh" contype="0" conaffinity="0" group="1" mesh="finger_tip"/>
          <geom type="mesh" mesh="finger_tip"/>
        </body>
      </body>
    </body>
  </worldbody>

  <actuator>
    <position name="act_Thumb_Opp" joint="right_hand_Thumb_Opposition" ctrlrange="0 0.988"/>
    <position name="act_Thumb_Flex" joint="right_hand_Thumb_Flexion" ctrlrange="0 0.970"/>
    <position name="act_j3" joint="right_hand_j3" ctrlrange="0 0.985"/>
    <position name="act_j4" joint="right_hand_j4" ctrlrange="0 1.406"/>
    <position name="act_j5" joint="right_hand_j5" ctrlrange="0 0.988"/>
    <position name="act_ring_spread" joint="right_hand_ring_spread" ctrlrange="0 0.288"/>
    <position name="act_Ring_Finger" joint="right_hand_Ring_Finger" ctrlrange="0 0.982"/>
    <position name="act_j12" joint="right_hand_j12" ctrlrange="0 1.334"/>
    <position name="act_j16" joint="right_hand_j16" ctrlrange="0 1.395"/>
    <position name="act_Finger_Spread" joint="right_hand_Finger_Spread" ctrlrange="0 0.583"/>
    <position name="act_Pinky" joint="right_hand_Pinky" ctrlrange="0 0.982"/>
    <position name="act_j13" joint="right_hand_j13" ctrlrange="0 1.334"/>
    <position name="act_j17" joint="right_hand_j17" ctrlrange="0 1.397"/>
    <position name="act_index_spread" joint="right_hand_index_spread" ctrlrange="0 0.288"/>
    <position name="act_Index_Prox" joint="right_hand_Index_Finger_Proximal" ctrlrange="0 0.798"/>
    <position name="act_Index_Dist" joint="right_hand_Index_Finger_Distal" ctrlrange="0 1.334"/>
    <position name="act_j14" joint="right_hand_j14" ctrlrange="0 1.394"/>
    <position name="act_Middle_Prox" joint="right_hand_Middle_Finger_Proximal" ctrlrange="0 0.798"/>
    <position name="act_Middle_Dist" joint="right_hand_Middle_Finger_Distal" ctrlrange="0 1.334"/>
    <position name="act_j15" joint="right_hand_j15" ctrlrange="0 1.334"/>
  </actuator>

  <contact>
    <exclude body1="right_hand_z" body2="right_hand_a"/>
    <exclude body1="right_hand_a" body2="right_hand_b"/>
    <exclude body1="right_hand_b" body2="right_hand_c"/>
    <exclude body1="right_hand_e2" body2="right_hand_virtual_j"/>
    <exclude body1="right_hand_e2" body2="right_hand_virtual_i"/>
    <exclude body1="right_hand_virtual_j" body2="right_hand_j"/>
    <exclude body1="right_hand_j" body2="right_hand_n"/>
    <exclude body1="right_hand_n" body2="right_hand_r"/>
    <exclude body1="right_hand_virtual_i" body2="right_hand_i"/>
    <exclude body1="right_hand_i" body2="right_hand_m"/>
    <exclude body1="right_hand_m" body2="right_hand_q"/>
    <exclude body1="right_hand_virtual_l" body2="right_hand_l"/>
    <exclude body1="right_hand_l" body2="right_hand_p"/>
    <exclude body1="right_hand_p" body2="right_hand_t"/>
    <exclude body1="right_hand_k" body2="right_hand_o"/>
    <exclude body1="right_hand_o" body2="right_hand_s"/>
  </contact>
</mujoco>
